Workbook
Name SG01_: Control!$B$2
Name SG02_: Control!$B$3
Name SG03_: Control!$B$4
Name SG04_: Control!$B$5
Name SG05_: Control!$B$6
Name SG06_: Control!$B$7
Name SG07_: Control!$B$8
Name SG08_: Control!$B$9
Name SG09_: Control!$B$10
Name SG10_: Control!$B$11
Name SG11_: Control!$B$12
Name SG12_: Control!$B$13
Name SG13_: Control!$B$14
Name SG14_: Control!$B$15
Name SG15_: Control!$B$16
Name Slicer_Cửa_hàng: #N/A

Sheet Control
A1: Cửa hàng | B1: Check | C1: DK1 | D1: DK2 | F1: Row Labels | G1: Sum of Check | L1: Cửa hàng | M1: Check
A2: SG01 | B2: =C2*D2 -> 1 | C2: =IFERROR(VLOOKUP(A2,$F$2:$G$14,2,0),0) -> 1 | D2: =IF(INDIRECT(A2&"!K10",TRUE)="",0,1) -> 1 | F2: SG01 | G2: 1 | L2: SG01 | M2: 1
A3: SG02 | B3: =C3*D3 -> 0 | C3: =IFERROR(VLOOKUP(A3,$F$2:$G$14,2,0),0) -> 0 | D3: =IF(INDIRECT(A3&"!K10",TRUE)="",0,1) -> 1 | F3: Grand Total | G3: 1 | L3: SG02 | M3: 1
A4: SG03 | B4: =C4*D4 -> 0 | C4: =IFERROR(VLOOKUP(A4,$F$2:$G$14,2,0),0) -> 0 | D4: =IF(INDIRECT(A4&"!K10",TRUE)="",0,1) -> 1 | L4: SG03 | M4: 1
A5: SG04 | B5: =C5*D5 -> 0 | C5: =IFERROR(VLOOKUP(A5,$F$2:$G$14,2,0),0) -> 0 | D5: =IF(INDIRECT(A5&"!K10",TRUE)="",0,1) -> 0 | L5: SG04 | M5: 1
A6: SG05 | B6: =C6*D6 -> 0 | C6: =IFERROR(VLOOKUP(A6,$F$2:$G$14,2,0),0) -> 0 | D6: =IF(INDIRECT(A6&"!K10",TRUE)="",0,1) -> 0 | L6: SG05 | M6: 1
A7: SG06 | B7: =C7*D7 -> 0 | C7: =IFERROR(VLOOKUP(A7,$F$2:$G$14,2,0),0) -> 0 | D7: =IF(INDIRECT(A7&"!K10",TRUE)="",0,1) -> 0 | L7: SG06 | M7: 1
A8: SG07 | B8: =C8*D8 -> 0 | C8: =IFERROR(VLOOKUP(A8,$F$2:$G$14,2,0),0) -> 0 | D8: =IF(INDIRECT(A8&"!K10",TRUE)="",0,1) -> 0 | L8: SG07 | M8: 1
A9: SG08 | B9: =C9*D9 -> 0 | C9: =IFERROR(VLOOKUP(A9,$F$2:$G$14,2,0),0) -> 0 | D9: =IF(INDIRECT(A9&"!K10",TRUE)="",0,1) -> 0 | L9: SG08 | M9: 1
A10: SG09 | B10: =C10*D10 -> 0 | C10: =IFERROR(VLOOKUP(A10,$F$2:$G$14,2,0),0) -> 0 | D10: =IF(INDIRECT(A10&"!K10",TRUE)="",0,1) -> 0 | L10: SG09 | M10: 1
A11: SG10 | B11: =C11*D11 -> 0 | C11: =IFERROR(VLOOKUP(A11,$F$2:$G$14,2,0),0) -> 0 | D11: =IF(INDIRECT(A11&"!K10",TRUE)="",0,1) -> 0 | L11: SG10 | M11: 1
A12: SG11 | B12: =C12*D12 -> 0 | C12: =IFERROR(VLOOKUP(A12,$F$2:$G$14,2,0),0) -> 0 | D12: =IF(INDIRECT(A12&"!K10",TRUE)="",0,1) -> 0 | L12: SG11 | M12: 1
A13: SG12 | B13: =C13*D13 -> 0 | C13: =IFERROR(VLOOKUP(A13,$F$2:$G$14,2,0),0) -> 0 | D13: =IF(INDIRECT(A13&"!K10",TRUE)="",0,1) -> 0 | L13: SG12 | M13: 1
A14: SG13 | B14: =C14*D14 -> 0 | C14: =IFERROR(VLOOKUP(A14,$F$2:$G$14,2,0),0) -> 0 | D14: =IF(INDIRECT(A14&"!K10",TRUE)="",0,1) -> 0 | L14: SG13 | M14: 1
A15: SG14 | B15: =C15*D15 -> 0 | C15: =IFERROR(VLOOKUP(A15,$F$2:$G$14,2,0),0) -> 0 | D15: =IF(INDIRECT(A15&"!K10",TRUE)="",0,1) -> 0 | L15: SG14 | M15: 1
A16: SG15 | B16: =C16*D16 -> 0 | C16: =IFERROR(VLOOKUP(A16,$F$2:$G$14,2,0),0) -> 0 | D16: =IF(INDIRECT(A16&"!K10",TRUE)="",0,1) -> 0 | L16: SG15 | M16: 1

Sheet MENU MIX GMSG T09.2026
B2: CTY CP TẦM NHÌN QUỐC TẾ ALADDIN - CHUỖI NHÀ HÀNG G.MASTER SÀI GÒN | G2: =L5 -> 1550563000 | M2: 4.2210468e+08 | V2: Star | W2: Bán nhiều - Lợi nhuận cao --> Phát huy
B3: BÁO CÁO MENU MIX (PRODUCT MIX) ĐỊNH KỲ | P3: =O3/7 -> 0 | V3: Horse | W3: Bán nhiều - Lợi nhuận thấp -->Điều chỉnh giá
B4: NHÀ HÀNG: | C4: (chọn NH muốn xem báo cáo menu mix trong danh sách) | K4: TC | L4: SALES | N4: TA | P4: COS | S4: Số bàn | T4: =(SUMIF('SG01'!$S$4,$S$4,'SG01'!$T$4)*SG01_+SUMIF('SG02'!$S$4,$S$4,'SG02'!$T$4)*SG02_+SUMIF('SG03'!$S$4,$S$4,'SG03'!$T$4)*SG03_+SUMIF('SG04'!$S$4,$S$4,'SG04'!$T$4)*SG04_+SUMIF('SG05'!$S$4,$S$4,'SG05'!$T$4)*SG05_+SUMIF('SG06'!$S$4,$S$4,'SG06'!$T$4)*SG06_+SUMIF('SG07'!$S$4,$S$4,'SG07'!$T$4)*SG07_+SUMIF('SG08'!$S$4,$S$4,'SG08'!$T$4)*SG08_+SUMIF('SG09'!$S$4,$S$4,'SG09'!$T$4)*SG09_+SUMIF('SG10'!$S$4,$S$4,'SG10'!$T$4)*SG10_+SUMIF('SG11'!$S$4,$S$4,'SG11'!$T$4)*SG11_+SUMIF('SG12'!$S$4,$S$4,'SG12'!$T$4)*SG12_+SUMIF('SG13'!$S$4,$S$4,'SG13'!$T$4)*SG13_+SUMIF('SG14'!$S$4,$S$4,'SG14'!$T$4)*SG14_+SUMIF('SG15'!$S$4,$S$4,'SG15'!$T$4)*SG15_) -> 1257 | V4: Puzzle | W4: Bán ít - Lợi nhuận cao --> Thúc đẩy bán hàng
B5: THÁNG: | C5: ='SG01'!C5:D5 -> 01.09.2026->30.09.2026 | G5: (Giữ phím Ctrl nếu muốn chọn nhiều nhà hàng xem cùng lúc) | K5: =(SUMIF('SG01'!$K$4,$K4,'SG01'!$K$5)*SG01_+SUMIF('SG02'!$K$4,$K4,'SG02'!$K$5)*SG02_+SUMIF('SG03'!$K$4,$K4,'SG03'!$K$5)*SG03_+SUMIF('SG04'!$K$4,$K4,'SG04'!$K$5)*SG04_+SUMIF('SG05'!$K$4,$K4,'SG05'!$K$5)*SG05_+SUMIF('SG06'!$K$4,$K4,'SG06'!$K$5)*SG06_+SUMIF('SG07'!$K$4,$K4,'SG07'!$K$5)*SG07_+SUMIF('SG08'!$K$4,$K4,'SG08'!$K$5)*SG08_+SUMIF('SG09'!$K$4,$K4,'SG09'!$K$5)*SG09_+SUMIF('SG10'!$K$4,$K4,'SG10'!$K$5)*SG10_+SUMIF('SG11'!$K$4,$K4,'SG11'!$K$5)*SG11_+SUMIF('SG12'!$K$4,$K4,'SG12'!$K$5)*SG12_+SUMIF('SG13'!$K$4,$K4,'SG13'!$K$5)*SG13_+SUMIF('SG14'!$K$4,$K4,'SG14'!$K$5)*SG14_+SUMIF('SG15'!$K$4,$K4,'SG15'!$K$5)*SG15_) -> 3693 | L5: =L10 -> 1550563000 | N5: =L5/K5 -> 419865.42 | P5: =K10/L10 -> 0.3364693 | S5: Số TC / Bàn: | T5: =K5/T4 -> 2.9379475 | V5: Dog | W5: Bán ít - lợi nhuận thấp --> Cân nhắc có thể thay thế | AC5: TC | AE5: =K5 -> 3693 | AI5: =(SUMIF('SG01'!$AB:$AB,$AC5,'SG01'!AH:AH)*SG01_+SUMIF('SG02'!$AB:$AB,$AC5,'SG02'!AH:AH)*SG02_+SUMIF('SG03'!$AB:$AB,$AC5,'SG03'!AH:AH)*SG03_+SUMIF('SG04'!$AB:$AB,$AC5,'SG04'!AH:AH)*SG04_+SUMIF('SG05'!$AB:$AB,$AC5,'SG05'!AH:AH)*SG05_+SUMIF('SG06'!$AB:$AB,$AC5,'SG06'!AH:AH)*SG06_+SUMIF('SG07'!$AB:$AB,$AC5,'SG07'!AH:AH)*SG07_+SUMIF('SG08'!$AB:$AB,$AC5,'SG08'!AH:AH)*SG08_+SUMIF('SG09'!$AB:$AB,$AC5,'SG09'!AH:AH)*SG09_+SUMIF('SG10'!$AB:$AB,$AC5,'SG10'!AH:AH)*SG10_+SUMIF('SG11'!$AB:$AB,$AC5,'SG11'!AH:AH)*SG11_+SUMIF('SG12'!$AB:$AB,$AC5,'SG12'!AH:AH)*SG12_+SUMIF('SG13'!$AB:$AB,$AC5,'SG13'!AH:AH)*SG13_+SUMIF('SG14'!$AB:$AB,$AC5,'SG14'!AH:AH)*SG14_+SUMIF('SG15'!$AB:$AB,$AC5,'SG15'!AH:AH)*SG15_) -> 3521
B6: 1 | C6: 2 | D6: 3 | E6: 4 | F6: 5 | G6: 6 | H6: 7 | I6: 8 | J6: 9 | K6: 10 | L6: 11 | M6: 12 | N6: 13 | O6: 14 | P6: 15 | Q6: 16 | R6: 17 | S6: 18 | T6: 19 | U6: 18 | V6: 19 | W6: 20 | X6: 21 | AD6: ='SG01'!AC6 -> 01.09.2026->30.09.2026 | AH6: ='SG01'!AG6 -> 01.09.2026->27.09.2026
B7: MÃ HÀNG | C7: TÊN HÀNG | D7: Ghi Chú | E7: Đơn Vị Tính | F7: Giá Vốn | G7: Giá Bán | H7: LN Món Bán | I7: Số Bán | K7: ITEM COST | L7: ITEM SALES | M7: MARGIN | N7: % COS | O7: % SALES MIX | P7: % MARGIN MIX | Q7: % PRODUCT MIX | R7: Per 100 TC | S7: Số Lượng Bán /100 Bàn | T7: Doanh Số Bán /100 Bàn | V7: Popularity | W7: Profitability | X7: Items class | AB7: MÃ NHÓM | AC7: TÊN NHÓM | AD7: ITEM SALES | AE7: TA | AF7: Item Sold | AG7: Per 100 TC | AH7: ITEM SALES | AI7: TA | AJ7: Item Sold | AK7: Per 100 TC | AL7: CLệch TA | AM7: CLệch Per 100TC
F8: Cost Price | G8: Selling Price | H8: Margin | I8: Item Sold | AD8: =SUM(AD9:AD43) -> 1471703000 | AE8: =SUM(AE9:AE43) -> 398511.51 | AF8: =SUM(AF9:AF43) -> 13974 | AG8: =SUM(AG9:AG43) -> 378.39155 | AH8: =SUM(AH9:AH43) -> 1403621000 | AI8: =SUM(AI9:AI43) -> 398642.72 | AJ8: =SUM(AJ9:AJ43) -> 13393 | AK8: =SUM(AK9:AK43) -> 380.37489 | ... AM8: =SUM(AM9:AM43) -> -1.9833419
AB9: CPL.BEP | AC9: CHI PHÍ QUẦY LINE NƯỚC CHẤM | AD9: =VLOOKUP(AB9,$B:$R,11,0) -> 0 | AE9: =AD9/AE$5 -> 0 | AF9: =VLOOKUP(AB9,$B:$R,8,0) -> 1 | AG9: =AF9/$AE$5*100 -> 0.027078256 | AH9: =(SUMIF('SG01'!$AA:$AA,$AB9,'SG01'!AG:AG)*SG01_+SUMIF('SG02'!$AA:$AA,$AB9,'SG02'!AG:AG)*SG02_+SUMIF('SG03'!$AA:$AA,$AB9,'SG03'!AG:AG)*SG03_+SUMIF('SG04'!$AA:$AA,$AB9,'SG04'!AG:AG)*SG04_+SUMIF('SG05'!$AA:$AA,$AB9,'SG05'!AG:AG)*SG05_+SUMIF('SG06'!$AA:$AA,$AB9,'SG06'!AG:AG)*SG06_+SUMIF('SG07'!$AA:$AA,$AB9,'SG07'!AG:AG)*SG07_+SUMIF('SG08'!$AA:$AA,$AB9,'SG08'!AG:AG)*SG08_+SUMIF('SG09'!$AA:$AA,$AB9,'SG09'!AG:AG)*SG09_+SUMIF('SG10'!$AA:$AA,$AB9,'SG10'!AG:AG)*SG10_+SUMIF('SG11'!$AA:$AA,$AB9,'SG11'!AG:AG)*SG11_+SUMIF('SG12'!$AA:$AA,$AB9,'SG12'!AG:AG)*SG12_+SUMIF('SG13'!$AA:$AA,$AB9,'SG13'!AG:AG)*SG13_+SUMIF('SG14'!$AA:$AA,$AB9,'SG14'!AG:AG)*SG14_+SUMIF('SG15'!$AA:$AA,$AB9,'SG15'!AG:AG)*SG15_) -> 0 | AI9: =AH9/AI$5 -> 0 | AJ9: =(SUMIF('SG01'!$AA:$AA,$AB9,'SG01'!AI:AI)*SG01_+SUMIF('SG02'!$AA:$AA,$AB9,'SG02'!AI:AI)*SG02_+SUMIF('SG03'!$AA:$AA,$AB9,'SG03'!AI:AI)*SG03_+SUMIF('SG04'!$AA:$AA,$AB9,'SG04'!AI:AI)*SG04_+SUMIF('SG05'!$AA:$AA,$AB9,'SG05'!AI:AI)*SG05_+SUMIF('SG06'!$AA:$AA,$AB9,'SG06'!AI:AI)*SG06_+SUMIF('SG07'!$AA:$AA,$AB9,'SG07'!AI:AI)*SG07_+SUMIF('SG08'!$AA:$AA,$AB9,'SG08'!AI:AI)*SG08_+SUMIF('SG09'!$AA:$AA,$AB9,'SG09'!AI:AI)*SG09_+SUMIF('SG10'!$AA:$AA,$AB9,'SG10'!AI:AI)*SG10_+SUMIF('SG11'!$AA:$AA,$AB9,'SG11'!AI:AI)*SG11_+SUMIF('SG12'!$AA:$AA,$AB9,'SG12'!AI:AI)*SG12_+SUMIF('SG13'!$AA:$AA,$AB9,'SG13'!AI:AI)*SG13_+SUMIF('SG14'!$AA:$AA,$AB9,'SG14'!AI:AI)*SG14_+SUMIF('SG15'!$AA:$AA,$AB9,'SG15'!AI:AI)*SG15_) -> 1 | AK9: =AJ9/$AI$5*100 -> 0.028401022 | AL9: =AE9-AI9 -> 0 | AM9: =AG9-AK9 -> -0.0013227663
B10: TỔNG MENU | I10: =SUBTOTAL(9,I12:I155) -> 16052 | K10: =SUBTOTAL(9,K12:K156) -> 5.2171684e+08 | L10: =SUBTOTAL(9,L12:L156) -> 1550563000 | M10: =SUBTOTAL(9,M12:M156) -> 1.0288462e+09 | N10: =K10/L10 -> 0.3364693 | O10: =L10/L$10 -> 1 | P10: =M10/M$10 -> 1 | Q10: =I10/I$10 -> 1 | R10: =I10/$K$5*100 -> 434.66017 | S10: =R10*T$5 -> 1277.0088 | T10: =SUBTOTAL(9,T12:T342) -> 1.2432959e+08 | V10: MIN Menu Selling | X10: 100 | AB10: KVI.GSG | AC10: KHAI VỊ | AD10: =VLOOKUP(AB10,$B:$M,11,0) -> 51978000 | AE10: =AD10/AE$5 -> 14074.736 | AF10: =VLOOKUP(AB10,$B:$R,8,0) -> 633 | AG10: =AF10/$AE$5*100 -> 17.140536 | AH10: =(SUMIF('SG01'!$AA:$AA,$AB10,'SG01'!AG:AG)*SG01_+SUMIF('SG02'!$AA:$AA,$AB10,'SG02'!AG:AG)*SG02_+SUMIF('SG03'!$AA:$AA,$AB10,'SG03'!AG:AG)*SG03_+SUMIF('SG04'!$AA:$AA,$AB10,'SG04'!AG:AG)*SG04_+SUMIF('SG05'!$AA:$AA,$AB10,'SG05'!AG:AG)*SG05_+SUMIF('SG06'!$AA:$AA,$AB10,'SG06'!AG:AG)*SG06_+SUMIF('SG07'!$AA:$AA,$AB10,'SG07'!AG:AG)*SG07_+SUMIF('SG08'!$AA:$AA,$AB10,'SG08'!AG:AG)*SG08_+SUMIF('SG09'!$AA:$AA,$AB10,'SG09'!AG:AG)*SG09_+SUMIF('SG10'!$AA:$AA,$AB10,'SG10'!AG:AG)*SG10_+SUMIF('SG11'!$AA:$AA,$AB10,'SG11'!AG:AG)*SG11_+SUMIF('SG12'!$AA:$AA,$AB10,'SG12'!AG:AG)*SG12_+SUMIF('SG13'!$AA:$AA,$AB10,'SG13'!AG:AG)*SG13_+SUMIF('SG14'!$AA:$AA,$AB10,'SG14'!AG:AG)*SG14_+SUMIF('SG15'!$AA:$AA,$AB10,'SG15'!AG:AG)*SG15_) -> 50538000 | AI10: =AH10/AI$5 -> 14353.309 | AJ10: =(SUMIF('SG01'!$AA:$AA,$AB10,'SG01'!AI:AI)*SG01_+SUMIF('SG02'!$AA:$AA,$AB10,'SG02'!AI:AI)*SG02_+SUMIF('SG03'!$AA:$AA,$AB10,'SG03'!AI:AI)*SG03_+SUMIF('SG04'!$AA:$AA,$AB10,'SG04'!AI:AI)*SG04_+SUMIF('SG05'!$AA:$AA,$AB10,'SG05'!AI:AI)*SG05_+SUMIF('SG06'!$AA:$AA,$AB10,'SG06'!AI:AI)*SG06_+SUMIF('SG07'!$AA:$AA,$AB10,'SG07'!AI:AI)*SG07_+SUMIF('SG08'!$AA:$AA,$AB10,'SG08'!AI:AI)*SG08_+SUMIF('SG09'!$AA:$AA,$AB10,'SG09'!AI:AI)*SG09_+SUMIF('SG10'!$AA:$AA,$AB10,'SG10'!AI:AI)*SG10_+SUMIF('SG11'!$AA:$AA,$AB10,'SG11'!AI:AI)*SG11_+SUMIF('SG12'!$AA:$AA,$AB10,'SG12'!AI:AI)*SG12_+SUMIF('SG13'!$AA:$AA,$AB10,'SG13'!AI:AI)*SG13_+SUMIF('SG14'!$AA:$AA,$AB10,'SG14'!AI:AI)*SG14_+SUMIF('SG15'!$AA:$AA,$AB10,'SG15'!AI:AI)*SG15_) -> 613 | AK10: =AJ10/$AI$5*100 -> 17.409827 | AL10: =AE10-AI10 -> -278.57273 | AM10: =AG10-AK10 -> -0.2692906
S11: =R11*T$5 -> 0 | T11: =IFERROR(S11*G11,0) -> 0 | AB11: XIENRCN.GSG | AC11: XIÊN RAU - CỦ - NẤM NƯỚNG | AD11: =VLOOKUP(AB11,$B:$M,11,0) -> 13427000 | AE11: =AD11/AE$5 -> 3635.7975 | AF11: =VLOOKUP(AB11,$B:$R,8,0) -> 755 | AG11: =AF11/$AE$5*100 -> 20.444083 | AH11: =(SUMIF('SG01'!$AA:$AA,$AB11,'SG01'!AG:AG)*SG01_+SUMIF('SG02'!$AA:$AA,$AB11,'SG02'!AG:AG)*SG02_+SUMIF('SG03'!$AA:$AA,$AB11,'SG03'!AG:AG)*SG03_+SUMIF('SG04'!$AA:$AA,$AB11,'SG04'!AG:AG)*SG04_+SUMIF('SG05'!$AA:$AA,$AB11,'SG05'!AG:AG)*SG05_+SUMIF('SG06'!$AA:$AA,$AB11,'SG06'!AG:AG)*SG06_+SUMIF('SG07'!$AA:$AA,$AB11,'SG07'!AG:AG)*SG07_+SUMIF('SG08'!$AA:$AA,$AB11,'SG08'!AG:AG)*SG08_+SUMIF('SG09'!$AA:$AA,$AB11,'SG09'!AG:AG)*SG09_+SUMIF('SG10'!$AA:$AA,$AB11,'SG10'!AG:AG)*SG10_+SUMIF('SG11'!$AA:$AA,$AB11,'SG11'!AG:AG)*SG11_+SUMIF('SG12'!$AA:$AA,$AB11,'SG12'!AG:AG)*SG12_+SUMIF('SG13'!$AA:$AA,$AB11,'SG13'!AG:AG)*SG13_+SUMIF('SG14'!$AA:$AA,$AB11,'SG14'!AG:AG)*SG14_+SUMIF('SG15'!$AA:$AA,$AB11,'SG15'!AG:AG)*SG15_) -> 13055000 | AI11: =AH11/AI$5 -> 3707.7535 | AJ11: =(SUMIF('SG01'!$AA:$AA,$AB11,'SG01'!AI:AI)*SG01_+SUMIF('SG02'!$AA:$AA,$AB11,'SG02'!AI:AI)*SG02_+SUMIF('SG03'!$AA:$AA,$AB11,'SG03'!AI:AI)*SG03_+SUMIF('SG04'!$AA:$AA,$AB11,'SG04'!AI:AI)*SG04_+SUMIF('SG05'!$AA:$AA,$AB11,'SG05'!AI:AI)*SG05_+SUMIF('SG06'!$AA:$AA,$AB11,'SG06'!AI:AI)*SG06_+SUMIF('SG07'!$AA:$AA,$AB11,'SG07'!AI:AI)*SG07_+SUMIF('SG08'!$AA:$AA,$AB11,'SG08'!AI:AI)*SG08_+SUMIF('SG09'!$AA:$AA,$AB11,'SG09'!AI:AI)*SG09_+SUMIF('SG10'!$AA:$AA,$AB11,'SG10'!AI:AI)*SG10_+SUMIF('SG11'!$AA:$AA,$AB11,'SG11'!AI:AI)*SG11_+SUMIF('SG12'!$AA:$AA,$AB11,'SG12'!AI:AI)*SG12_+SUMIF('SG13'!$AA:$AA,$AB11,'SG13'!AI:AI)*SG13_+SUMIF('SG14'!$AA:$AA,$AB11,'SG14'!AI:AI)*SG14_+SUMIF('SG15'!$AA:$AA,$AB11,'SG15'!AI:AI)*SG15_) -> 733 | AK11: =AJ11/$AI$5*100 -> 20.817949 | AL11: =AE11-AI11 -> -71.956024 | AM11: =AG11-AK11 -> -0.37386605
B12: MÓN ĂN | I12: =SUBTOTAL(9,I14:I112) -> 8244 | K12: =SUBTOTAL(9,K14:K112) -> 4.6307738e+08 | L12: =SUBTOTAL(9,L14:L112) -> 1403263000 | M12: =SUBTOTAL(9,M14:M112) -> 9.4018562e+08 | N12: =K12/L12 -> 0.33000042 | O12: =L12/L$10 -> 0.90500225 | P12: =M12/M$10 -> 0.91382527 | Q12: =I12/I$10 -> 0.51358086 | R12: =I12/$K$5*100 -> 223.23314 | S12: =R12*T$5 -> 655.84726 | T12: =IFERROR(S12*G12,0) -> 0 | V12: MIN Sales Contribution | X12: =3000000*SUM(Control!$B$2:$B$11) -> 3000000 | AB12: XIENTHIT.GSG | AC12: XIÊN THỊT NƯỚNG | AD12: =VLOOKUP(AB12,$B:$M,11,0) -> 66828000 | AE12: =AD12/AE$5 -> 18095.857 | AF12: =VLOOKUP(AB12,$B:$R,8,0) -> 1651 | AG12: =AF12/$AE$5*100 -> 44.706201 | AH12: =(SUMIF('SG01'!$AA:$AA,$AB12,'SG01'!AG:AG)*SG01_+SUMIF('SG02'!$AA:$AA,$AB12,'SG02'!AG:AG)*SG02_+SUMIF('SG03'!$AA:$AA,$AB12,'SG03'!AG:AG)*SG03_+SUMIF('SG04'!$AA:$AA,$AB12,'SG04'!AG:AG)*SG04_+SUMIF('SG05'!$AA:$AA,$AB12,'SG05'!AG:AG)*SG05_+SUMIF('SG06'!$AA:$AA,$AB12,'SG06'!AG:AG)*SG06_+SUMIF('SG07'!$AA:$AA,$AB12,'SG07'!AG:AG)*SG07_+SUMIF('SG08'!$AA:$AA,$AB12,'SG08'!AG:AG)*SG08_+SUMIF('SG09'!$AA:$AA,$AB12,'SG09'!AG:AG)*SG09_+SUMIF('SG10'!$AA:$AA,$AB12,'SG10'!AG:AG)*SG10_+SUMIF('SG11'!$AA:$AA,$AB12,'SG11'!AG:AG)*SG11_+SUMIF('SG12'!$AA:$AA,$AB12,'SG12'!AG:AG)*SG12_+SUMIF('SG13'!$AA:$AA,$AB12,'SG13'!AG:AG)*SG13_+SUMIF('SG14'!$AA:$AA,$AB12,'SG14'!AG:AG)*SG14_+SUMIF('SG15'!$AA:$AA,$AB12,'SG15'!AG:AG)*SG15_) -> 64692000 | AI12: =AH12/AI$5 -> 18373.189 | AJ12: =(SUMIF('SG01'!$AA:$AA,$AB12,'SG01'!AI:AI)*SG01_+SUMIF('SG02'!$AA:$AA,$AB12,'SG02'!AI:AI)*SG02_+SUMIF('SG03'!$AA:$AA,$AB12,'SG03'!AI:AI)*SG03_+SUMIF('SG04'!$AA:$AA,$AB12,'SG04'!AI:AI)*SG04_+SUMIF('SG05'!$AA:$AA,$AB12,'SG05'!AI:AI)*SG05_+SUMIF('SG06'!$AA:$AA,$AB12,'SG06'!AI:AI)*SG06_+SUMIF('SG07'!$AA:$AA,$AB12,'SG07'!AI:AI)*SG07_+SUMIF('SG08'!$AA:$AA,$AB12,'SG08'!AI:AI)*SG08_+SUMIF('SG09'!$AA:$AA,$AB12,'SG09'!AI:AI)*SG09_+SUMIF('SG10'!$AA:$AA,$AB12,'SG10'!AI:AI)*SG10_+SUMIF('SG11'!$AA:$AA,$AB12,'SG11'!AI:AI)*SG11_+SUMIF('SG12'!$AA:$AA,$AB12,'SG12'!AI:AI)*SG12_+SUMIF('SG13'!$AA:$AA,$AB12,'SG13'!AI:AI)*SG13_+SUMIF('SG14'!$AA:$AA,$AB12,'SG14'!AI:AI)*SG14_+SUMIF('SG15'!$AA:$AA,$AB12,'SG15'!AI:AI)*SG15_) -> 1594 | AK12: =AJ12/$AI$5*100 -> 45.27123 | AL12: =AE12-AI12 -> -277.33241 | AM12: =AG12-AK12 -> -0.56502884
AB13: THITBO.GSG | AC13: THỊT BÒ | AD13: =VLOOKUP(AB13,$B:$M,11,0) -> 346497000 | AE13: =AD13/AE$5 -> 93825.345 | AF13: =VLOOKUP(AB13,$B:$R,8,0) -> 1717 | AG13: =AF13/$AE$5*100 -> 46.493366 | AH13: =(SUMIF('SG01'!$AA:$AA,$AB13,'SG01'!AG:AG)*SG01_+SUMIF('SG02'!$AA:$AA,$AB13,'SG02'!AG:AG)*SG02_+SUMIF('SG03'!$AA:$AA,$AB13,'SG03'!AG:AG)*SG03_+SUMIF('SG04'!$AA:$AA,$AB13,'SG04'!AG:AG)*SG04_+SUMIF('SG05'!$AA:$AA,$AB13,'SG05'!AG:AG)*SG05_+SUMIF('SG06'!$AA:$AA,$AB13,'SG06'!AG:AG)*SG06_+SUMIF('SG07'!$AA:$AA,$AB13,'SG07'!AG:AG)*SG07_+SUMIF('SG08'!$AA:$AA,$AB13,'SG08'!AG:AG)*SG08_+SUMIF('SG09'!$AA:$AA,$AB13,'SG09'!AG:AG)*SG09_+SUMIF('SG10'!$AA:$AA,$AB13,'SG10'!AG:AG)*SG10_+SUMIF('SG11'!$AA:$AA,$AB13,'SG11'!AG:AG)*SG11_+SUMIF('SG12'!$AA:$AA,$AB13,'SG12'!AG:AG)*SG12_+SUMIF('SG13'!$AA:$AA,$AB13,'SG13'!AG:AG)*SG13_+SUMIF('SG14'!$AA:$AA,$AB13,'SG14'!AG:AG)*SG14_+SUMIF('SG15'!$AA:$AA,$AB13,'SG15'!AG:AG)*SG15_) -> 334514000 | AI13: =AH13/AI$5 -> 95005.396 | AJ13: =(SUMIF('SG01'!$AA:$AA,$AB13,'SG01'!AI:AI)*SG01_+SUMIF('SG02'!$AA:$AA,$AB13,'SG02'!AI:AI)*SG02_+SUMIF('SG03'!$AA:$AA,$AB13,'SG03'!AI:AI)*SG03_+SUMIF('SG04'!$AA:$AA,$AB13,'SG04'!AI:AI)*SG04_+SUMIF('SG05'!$AA:$AA,$AB13,'SG05'!AI:AI)*SG05_+SUMIF('SG06'!$AA:$AA,$AB13,'SG06'!AI:AI)*SG06_+SUMIF('SG07'!$AA:$AA,$AB13,'SG07'!AI:AI)*SG07_+SUMIF('SG08'!$AA:$AA,$AB13,'SG08'!AI:AI)*SG08_+SUMIF('SG09'!$AA:$AA,$AB13,'SG09'!AI:AI)*SG09_+SUMIF('SG10'!$AA:$AA,$AB13,'SG10'!AI:AI)*SG10_+SUMIF('SG11'!$AA:$AA,$AB13,'SG11'!AI:AI)*SG11_+SUMIF('SG12'!$AA:$AA,$AB13,'SG12'!AI:AI)*SG12_+SUMIF('SG13'!$AA:$AA,$AB13,'SG13'!AI:AI)*SG13_+SUMIF('SG14'!$AA:$AA,$AB13,'SG14'!AI:AI)*SG14_+SUMIF('SG15'!$AA:$AA,$AB13,'SG15'!AI:AI)*SG15_) -> 1655 | AK13: =AJ13/$AI$5*100 -> 47.003692 | AL13: =AE13-AI13 -> -1180.0509 | AM13: =AG13-AK13 -> -0.51032631
B14: CPL.BEP | C14: CHI PHÍ QUẦY LINE NƯỚC CHẤM | I14: =SUBTOTAL(9,I15:I16) -> 1 | K14: =SUBTOTAL(9,K15:K16) -> 34599678 | L14: =SUBTOTAL(9,L15:L16) -> 0 | M14: =SUBTOTAL(9,M15:M16) -> -34599678 | N14: =K14/L14 -> #DIV/0! | O14: =L14/L$10 -> 0 | P14: =M14/M$10 -> -0.033629594 | Q14: =I14/I$10 -> 6.2297533e-05 | R14: =I14/$K$5*100 -> 0.027078256 | S14: =R14*T$5 -> 0.079554495 | T14: =IFERROR(S14*G14,0) -> 0 | AB14: THITHEO.GSG | AC14: THỊT HEO | AD14: =VLOOKUP(AB14,$B:$M,11,0) -> 75740000 | AE14: =AD14/AE$5 -> 20509.071 | AF14: =VLOOKUP(AB14,$B:$R,8,0) -> 750 | AG14: =AF14/$AE$5*100 -> 20.308692 | AH14: =(SUMIF('SG01'!$AA:$AA,$AB14,'SG01'!AG:AG)*SG01_+SUMIF('SG02'!$AA:$AA,$AB14,'SG02'!AG:AG)*SG02_+SUMIF('SG03'!$AA:$AA,$AB14,'SG03'!AG:AG)*SG03_+SUMIF('SG04'!$AA:$AA,$AB14,'SG04'!AG:AG)*SG04_+SUMIF('SG05'!$AA:$AA,$AB14,'SG05'!AG:AG)*SG05_+SUMIF('SG06'!$AA:$AA,$AB14,'SG06'!AG:AG)*SG06_+SUMIF('SG07'!$AA:$AA,$AB14,'SG07'!AG:AG)*SG07_+SUMIF('SG08'!$AA:$AA,$AB14,'SG08'!AG:AG)*SG08_+SUMIF('SG09'!$AA:$AA,$AB14,'SG09'!AG:AG)*SG09_+SUMIF('SG10'!$AA:$AA,$AB14,'SG10'!AG:AG)*SG10_+SUMIF('SG11'!$AA:$AA,$AB14,'SG11'!AG:AG)*SG11_+SUMIF('SG12'!$AA:$AA,$AB14,'SG12'!AG:AG)*SG12_+SUMIF('SG13'!$AA:$AA,$AB14,'SG13'!AG:AG)*SG13_+SUMIF('SG14'!$AA:$AA,$AB14,'SG14'!AG:AG)*SG14_+SUMIF('SG15'!$AA:$AA,$AB14,'SG15'!AG:AG)*SG15_) -> 72275000 | AI14: =AH14/AI$5 -> 20526.839 | AJ14: =(SUMIF('SG01'!$AA:$AA,$AB14,'SG01'!AI:AI)*SG01_+SUMIF('SG02'!$AA:$AA,$AB14,'SG02'!AI:AI)*SG02_+SUMIF('SG03'!$AA:$AA,$AB14,'SG03'!AI:AI)*SG03_+SUMIF('SG04'!$AA:$AA,$AB14,'SG04'!AI:AI)*SG04_+SUMIF('SG05'!$AA:$AA,$AB14,'SG05'!AI:AI)*SG05_+SUMIF('SG06'!$AA:$AA,$AB14,'SG06'!AI:AI)*SG06_+SUMIF('SG07'!$AA:$AA,$AB14,'SG07'!AI:AI)*SG07_+SUMIF('SG08'!$AA:$AA,$AB14,'SG08'!AI:AI)*SG08_+SUMIF('SG09'!$AA:$AA,$AB14,'SG09'!AI:AI)*SG09_+SUMIF('SG10'!$AA:$AA,$AB14,'SG10'!AI:AI)*SG10_+SUMIF('SG11'!$AA:$AA,$AB14,'SG11'!AI:AI)*SG11_+SUMIF('SG12'!$AA:$AA,$AB14,'SG12'!AI:AI)*SG12_+SUMIF('SG13'!$AA:$AA,$AB14,'SG13'!AI:AI)*SG13_+SUMIF('SG14'!$AA:$AA,$AB14,'SG14'!AI:AI)*SG14_+SUMIF('SG15'!$AA:$AA,$AB14,'SG15'!AI:AI)*SG15_) -> 715 | AK14: =AJ14/$AI$5*100 -> 20.306731 | AL14: =AE14-AI14 -> -17.76775 | AM14: =AG14-AK14 -> 0.0019610779
A15: 1 | B15: LINEBEP | C15: =VLOOKUP(B15,'SG01'!$B:$E,2,0) -> Chi phí quầy line nước chấm | F15: 9368.9895 | G15: =L15/I15 -> 0 | H15: =G15-F15 -> -9368.9895 | I15: =(SUMIF('SG01'!$B:$B,$B15,'SG01'!I:I)*SG01_+SUMIF('SG02'!$B:$B,$B15,'SG02'!I:I)*SG02_+SUMIF('SG03'!$B:$B,$B15,'SG03'!I:I)*SG03_+SUMIF('SG04'!$B:$B,$B15,'SG04'!I:I)*SG04_+SUMIF('SG05'!$B:$B,$B15,'SG05'!I:I)*SG05_+SUMIF('SG06'!$B:$B,$B15,'SG06'!I:I)*SG06_+SUMIF('SG07'!$B:$B,$B15,'SG07'!I:I)*SG07_+SUMIF('SG08'!$B:$B,$B15,'SG08'!I:I)*SG08_+SUMIF('SG09'!$B:$B,$B15,'SG09'!I:I)*SG09_+SUMIF('SG10'!$B:$B,$B15,'SG10'!I:I)*SG10_+SUMIF('SG11'!$B:$B,$B15,'SG11'!I:I)*SG11_+SUMIF('SG12'!$B:$B,$B15,'SG12'!I:I)*SG12_+SUMIF('SG13'!$B:$B,$B15,'SG13'!I:I)*SG13_+SUMIF('SG14'!$B:$B,$B15,'SG14'!I:I)*SG14_+SUMIF('SG15'!$B:$B,$B15,'SG15'!I:I)*SG15_) -> 1 | K15: =(SUMIF('SG01'!$B:$B,$B15,'SG01'!K:K)*SG01_+SUMIF('SG02'!$B:$B,$B15,'SG02'!K:K)*SG02_+SUMIF('SG03'!$B:$B,$B15,'SG03'!K:K)*SG03_+SUMIF('SG04'!$B:$B,$B15,'SG04'!K:K)*SG04_+SUMIF('SG05'!$B:$B,$B15,'SG05'!K:K)*SG05_+SUMIF('SG06'!$B:$B,$B15,'SG06'!K:K)*SG06_+SUMIF('SG07'!$B:$B,$B15,'SG07'!K:K)*SG07_+SUMIF('SG08'!$B:$B,$B15,'SG08'!K:K)*SG08_+SUMIF('SG09'!$B:$B,$B15,'SG09'!K:K)*SG09_+SUMIF('SG10'!$B:$B,$B15,'SG10'!K:K)*SG10_+SUMIF('SG11'!$B:$B,$B15,'SG11'!K:K)*SG11_+SUMIF('SG12'!$B:$B,$B15,'SG12'!K:K)*SG12_+SUMIF('SG13'!$B:$B,$B15,'SG13'!K:K)*SG13_+SUMIF('SG14'!$B:$B,$B15,'SG14'!K:K)*SG14_+SUMIF('SG15'!$B:$B,$B15,'SG15'!K:K)*SG15_) -> 34599678 | L15: =(SUMIF('SG01'!$B:$B,$B15,'SG01'!L:L)*SG01_+SUMIF('SG02'!$B:$B,$B15,'SG02'!L:L)*SG02_+SUMIF('SG03'!$B:$B,$B15,'SG03'!L:L)*SG03_+SUMIF('SG04'!$B:$B,$B15,'SG04'!L:L)*SG04_+SUMIF('SG05'!$B:$B,$B15,'SG05'!L:L)*SG05_+SUMIF('SG06'!$B:$B,$B15,'SG06'!L:L)*SG06_+SUMIF('SG07'!$B:$B,$B15,'SG07'!L:L)*SG07_+SUMIF('SG08'!$B:$B,$B15,'SG08'!L:L)*SG08_+SUMIF('SG09'!$B:$B,$B15,'SG09'!L:L)*SG09_+SUMIF('SG10'!$B:$B,$B15,'SG10'!L:L)*SG10_+SUMIF('SG11'!$B:$B,$B15,'SG11'!L:L)*SG11_+SUMIF('SG12'!$B:$B,$B15,'SG12'!L:L)*SG12_+SUMIF('SG13'!$B:$B,$B15,'SG13'!L:L)*SG13_+SUMIF('SG14'!$B:$B,$B15,'SG14'!L:L)*SG14_+SUMIF('SG15'!$B:$B,$B15,'SG15'!L:L)*SG15_) -> 0 | M15: =L15-K15 -> -34599678 | N15: =K15/L15 -> #DIV/0! | O15: =L15/L$10 -> 0 | P15: =M15/M$10 -> -0.033629594 | Q15: =I15/I$10 -> 6.2297533e-05 | R15: =I15/$K$5*100 -> 0.027078256 | S15: =R15*T$5 -> 0.079554495 | T15: =IFERROR(S15*G15,0) -> 0 | V15: =IF(B15<>"",IFERROR(IF($I15>=$X$10,"High","Low"),""),"") -> Low | W15: =IF(B15<>"",IFERROR(IF($L15>=$X$12,"High","Low"),""),"") -> Low | X15: =IF(B15<>"",IFERROR(IF(AND(V15="high",W15="high"),"Star",IF(AND(V15="low",W15="high"),"Puzzle",(IF(AND(V15="high",W15="low"),"Horse","Dog")))),""),"") -> Dog | AB15: HSAN.GSG | AC15: HẢI SẢN | AD15: =VLOOKUP(AB15,$B:$M,11,0) -> 66870000 | AE15: =AD15/AE$5 -> 18107.23 | AF15: =VLOOKUP(AB15,$B:$R,8,0) -> 521 | AG15: =AF15/$AE$5*100 -> 14.107771 | AH15: =(SUMIF('SG01'!$AA:$AA,$AB15,'SG01'!AG:AG)*SG01_+SUMIF('SG02'!$AA:$AA,$AB15,'SG02'!AG:AG)*SG02_+SUMIF('SG03'!$AA:$AA,$AB15,'SG03'!AG:AG)*SG03_+SUMIF('SG04'!$AA:$AA,$AB15,'SG04'!AG:AG)*SG04_+SUMIF('SG05'!$AA:$AA,$AB15,'SG05'!AG:AG)*SG05_+SUMIF('SG06'!$AA:$AA,$AB15,'SG06'!AG:AG)*SG06_+SUMIF('SG07'!$AA:$AA,$AB15,'SG07'!AG:AG)*SG07_+SUMIF('SG08'!$AA:$AA,$AB15,'SG08'!AG:AG)*SG08_+SUMIF('SG09'!$AA:$AA,$AB15,'SG09'!AG:AG)*SG09_+SUMIF('SG10'!$AA:$AA,$AB15,'SG10'!AG:AG)*SG10_+SUMIF('SG11'!$AA:$AA,$AB15,'SG11'!AG:AG)*SG11_+SUMIF('SG12'!$AA:$AA,$AB15,'SG12'!AG:AG)*SG12_+SUMIF('SG13'!$AA:$AA,$AB15,'SG13'!AG:AG)*SG13_+SUMIF('SG14'!$AA:$AA,$AB15,'SG14'!AG:AG)*SG14_+SUMIF('SG15'!$AA:$AA,$AB15,'SG15'!AG:AG)*SG15_) -> 65500000 | AI15: =AH15/AI$5 -> 18602.67 | AJ15: =(SUMIF('SG01'!$AA:$AA,$AB15,'SG01'!AI:AI)*SG01_+SUMIF('SG02'!$AA:$AA,$AB15,'SG02'!AI:AI)*SG02_+SUMIF('SG03'!$AA:$AA,$AB15,'SG03'!AI:AI)*SG03_+SUMIF('SG04'!$AA:$AA,$AB15,'SG04'!AI:AI)*SG04_+SUMIF('SG05'!$AA:$AA,$AB15,'SG05'!AI:AI)*SG05_+SUMIF('SG06'!$AA:$AA,$AB15,'SG06'!AI:AI)*SG06_+SUMIF('SG07'!$AA:$AA,$AB15,'SG07'!AI:AI)*SG07_+SUMIF('SG08'!$AA:$AA,$AB15,'SG08'!AI:AI)*SG08_+SUMIF('SG09'!$AA:$AA,$AB15,'SG09'!AI:AI)*SG09_+SUMIF('SG10'!$AA:$AA,$AB15,'SG10'!AI:AI)*SG10_+SUMIF('SG11'!$AA:$AA,$AB15,'SG11'!AI:AI)*SG11_+SUMIF('SG12'!$AA:$AA,$AB15,'SG12'!AI:AI)*SG12_+SUMIF('SG13'!$AA:$AA,$AB15,'SG13'!AI:AI)*SG13_+SUMIF('SG14'!$AA:$AA,$AB15,'SG14'!AI:AI)*SG14_+SUMIF('SG15'!$AA:$AA,$AB15,'SG15'!AI:AI)*SG15_) -> 508 | AK15: =AJ15/$AI$5*100 -> 14.427719 | AL15: =AE15-AI15 -> -495.4398 | AM15: =AG15-AK15 -> -0.31994794
AB16: ANKEM.GSG | AC16: CÁC MÓN DÙNG KÈM | AD16: =VLOOKUP(AB16,$B:$M,11,0) -> 104162000 | AE16: =AD16/AE$5 -> 28205.253 | AF16: =VLOOKUP(AB16,$B:$R,8,0) -> 1369 | AG16: =AF16/$AE$5*100 -> 37.070133 | AH16: =(SUMIF('SG01'!$AA:$AA,$AB16,'SG01'!AG:AG)*SG01_+SUMIF('SG02'!$AA:$AA,$AB16,'SG02'!AG:AG)*SG02_+SUMIF('SG03'!$AA:$AA,$AB16,'SG03'!AG:AG)*SG03_+SUMIF('SG04'!$AA:$AA,$AB16,'SG04'!AG:AG)*SG04_+SUMIF('SG05'!$AA:$AA,$AB16,'SG05'!AG:AG)*SG05_+SUMIF('SG06'!$AA:$AA,$AB16,'SG06'!AG:AG)*SG06_+SUMIF('SG07'!$AA:$AA,$AB16,'SG07'!AG:AG)*SG07_+SUMIF('SG08'!$AA:$AA,$AB16,'SG08'!AG:AG)*SG08_+SUMIF('SG09'!$AA:$AA,$AB16,'SG09'!AG:AG)*SG09_+SUMIF('SG10'!$AA:$AA,$AB16,'SG10'!AG:AG)*SG10_+SUMIF('SG11'!$AA:$AA,$AB16,'SG11'!AG:AG)*SG11_+SUMIF('SG12'!$AA:$AA,$AB16,'SG12'!AG:AG)*SG12_+SUMIF('SG13'!$AA:$AA,$AB16,'SG13'!AG:AG)*SG13_+SUMIF('SG14'!$AA:$AA,$AB16,'SG14'!AG:AG)*SG14_+SUMIF('SG15'!$AA:$AA,$AB16,'SG15'!AG:AG)*SG15_) -> 100737000 | AI16: =AH16/AI$5 -> 28610.338 | AJ16: =(SUMIF('SG01'!$AA:$AA,$AB16,'SG01'!AI:AI)*SG01_+SUMIF('SG02'!$AA:$AA,$AB16,'SG02'!AI:AI)*SG02_+SUMIF('SG03'!$AA:$AA,$AB16,'SG03'!AI:AI)*SG03_+SUMIF('SG04'!$AA:$AA,$AB16,'SG04'!AI:AI)*SG04_+SUMIF('SG05'!$AA:$AA,$AB16,'SG05'!AI:AI)*SG05_+SUMIF('SG06'!$AA:$AA,$AB16,'SG06'!AI:AI)*SG06_+SUMIF('SG07'!$AA:$AA,$AB16,'SG07'!AI:AI)*SG07_+SUMIF('SG08'!$AA:$AA,$AB16,'SG08'!AI:AI)*SG08_+SUMIF('SG09'!$AA:$AA,$AB16,'SG09'!AI:AI)*SG09_+SUMIF('SG10'!$AA:$AA,$AB16,'SG10'!AI:AI)*SG10_+SUMIF('SG11'!$AA:$AA,$AB16,'SG11'!AI:AI)*SG11_+SUMIF('SG12'!$AA:$AA,$AB16,'SG12'!AI:AI)*SG12_+SUMIF('SG13'!$AA:$AA,$AB16,'SG13'!AI:AI)*SG13_+SUMIF('SG14'!$AA:$AA,$AB16,'SG14'!AI:AI)*SG14_+SUMIF('SG15'!$AA:$AA,$AB16,'SG15'!AI:AI)*SG15_) -> 1318 | AK16: =AJ16/$AI$5*100 -> 37.432548 | AL16: =AE16-AI16 -> -405.08479 | AM16: =AG16-AK16 -> -0.36241489
B17: KVI.GSG | C17: KHAI VỊ | I17: =SUBTOTAL(9,I18:I31) -> 633 | K17: =SUBTOTAL(9,K18:K31) -> 14750648 | L17: =SUBTOTAL(9,L18:L31) -> 51978000 | M17: =SUBTOTAL(9,M18:M31) -> 37227352 | N17: =K17/L17 -> 0.28378638 | O17: =L17/L$10 -> 0.033522017 | P17: =M17/M$10 -> 0.036183594 | Q17: =I17/I$10 -> 0.039434338 | R17: =I17/$K$5*100 -> 17.140536 | S17: =R17*T$5 -> 50.357995 | T17: =IFERROR(S17*G17,0) -> 0 | AB17: COMBO.GSG | AC17: COMBO HONG KONG | AD17: =VLOOKUP(AB17,$B:$M,11,0) -> 677761000 | AE17: =AD17/AE$5 -> 183525.86 | AF17: =VLOOKUP(AB17,$B:$R,8,0) -> 847 | AG17: =AF17/$AE$5*100 -> 22.935283 | AH17: =(SUMIF('SG01'!$AA:$AA,$AB17,'SG01'!AG:AG)*SG01_+SUMIF('SG02'!$AA:$AA,$AB17,'SG02'!AG:AG)*SG02_+SUMIF('SG03'!$AA:$AA,$AB17,'SG03'!AG:AG)*SG03_+SUMIF('SG04'!$AA:$AA,$AB17,'SG04'!AG:AG)*SG04_+SUMIF('SG05'!$AA:$AA,$AB17,'SG05'!AG:AG)*SG05_+SUMIF('SG06'!$AA:$AA,$AB17,'SG06'!AG:AG)*SG06_+SUMIF('SG07'!$AA:$AA,$AB17,'SG07'!AG:AG)*SG07_+SUMIF('SG08'!$AA:$AA,$AB17,'SG08'!AG:AG)*SG08_+SUMIF('SG09'!$AA:$AA,$AB17,'SG09'!AG:AG)*SG09_+SUMIF('SG10'!$AA:$AA,$AB17,'SG10'!AG:AG)*SG10_+SUMIF('SG11'!$AA:$AA,$AB17,'SG11'!AG:AG)*SG11_+SUMIF('SG12'!$AA:$AA,$AB17,'SG12'!AG:AG)*SG12_+SUMIF('SG13'!$AA:$AA,$AB17,'SG13'!AG:AG)*SG13_+SUMIF('SG14'!$AA:$AA,$AB17,'SG14'!AG:AG)*SG14_+SUMIF('SG15'!$AA:$AA,$AB17,'SG15'!AG:AG)*SG15_) -> 637403000 | AI17: =AH17/AI$5 -> 181028.97 | AJ17: =(SUMIF('SG01'!$AA:$AA,$AB17,'SG01'!AI:AI)*SG01_+SUMIF('SG02'!$AA:$AA,$AB17,'SG02'!AI:AI)*SG02_+SUMIF('SG03'!$AA:$AA,$AB17,'SG03'!AI:AI)*SG03_+SUMIF('SG04'!$AA:$AA,$AB17,'SG04'!AI:AI)*SG04_+SUMIF('SG05'!$AA:$AA,$AB17,'SG05'!AI:AI)*SG05_+SUMIF('SG06'!$AA:$AA,$AB17,'SG06'!AI:AI)*SG06_+SUMIF('SG07'!$AA:$AA,$AB17,'SG07'!AI:AI)*SG07_+SUMIF('SG08'!$AA:$AA,$AB17,'SG08'!AI:AI)*SG08_+SUMIF('SG09'!$AA:$AA,$AB17,'SG09'!AI:AI)*SG09_+SUMIF('SG10'!$AA:$AA,$AB17,'SG10'!AI:AI)*SG10_+SUMIF('SG11'!$AA:$AA,$AB17,'SG11'!AI:AI)*SG11_+SUMIF('SG12'!$AA:$AA,$AB17,'SG12'!AI:AI)*SG12_+SUMIF('SG13'!$AA:$AA,$AB17,'SG13'!AI:AI)*SG13_+SUMIF('SG14'!$AA:$AA,$AB17,'SG14'!AI:AI)*SG14_+SUMIF('SG15'!$AA:$AA,$AB17,'SG15'!AI:AI)*SG15_) -> 796 | AK17: =AJ17/$AI$5*100 -> 22.607214 | AL17: =AE17-AI17 -> 2496.8907 | AM17: =AG17-AK17 -> 0.32806911
A18: 1 | B18: GSKVI002 | C18: =VLOOKUP(B18,'SG01'!$B:$E,2,0) -> Khoai Tây Lắc Phô Mai | E18: =VLOOKUP(B18,'SG01'!$B:$E,4,0) -> Phần | F18: =K18/I18 -> 15238.609 | G18: =L18/I18 -> 61084.337 | H18: =G18-F18 -> 45845.728 | I18: =(SUMIF('SG01'!$B:$B,$B18,'SG01'!I:I)*SG01_+SUMIF('SG02'!$B:$B,$B18,'SG02'!I:I)*SG02_+SUMIF('SG03'!$B:$B,$B18,'SG03'!I:I)*SG03_+SUMIF('SG04'!$B:$B,$B18,'SG04'!I:I)*SG04_+SUMIF('SG05'!$B:$B,$B18,'SG05'!I:I)*SG05_+SUMIF('SG06'!$B:$B,$B18,'SG06'!I:I)*SG06_+SUMIF('SG07'!$B:$B,$B18,'SG07'!I:I)*SG07_+SUMIF('SG08'!$B:$B,$B18,'SG08'!I:I)*SG08_+SUMIF('SG09'!$B:$B,$B18,'SG09'!I:I)*SG09_+SUMIF('SG10'!$B:$B,$B18,'SG10'!I:I)*SG10_+SUMIF('SG11'!$B:$B,$B18,'SG11'!I:I)*SG11_+SUMIF('SG12'!$B:$B,$B18,'SG12'!I:I)*SG12_+SUMIF('SG13'!$B:$B,$B18,'SG13'!I:I)*SG13_+SUMIF('SG14'!$B:$B,$B18,'SG14'!I:I)*SG14_+SUMIF('SG15'!$B:$B,$B18,'SG15'!I:I)*SG15_) -> 83 | K18: =(SUMIF('SG01'!$B:$B,$B18,'SG01'!K:K)*SG01_+SUMIF('SG02'!$B:$B,$B18,'SG02'!K:K)*SG02_+SUMIF('SG03'!$B:$B,$B18,'SG03'!K:K)*SG03_+SUMIF('SG04'!$B:$B,$B18,'SG04'!K:K)*SG04_+SUMIF('SG05'!$B:$B,$B18,'SG05'!K:K)*SG05_+SUMIF('SG06'!$B:$B,$B18,'SG06'!K:K)*SG06_+SUMIF('SG07'!$B:$B,$B18,'SG07'!K:K)*SG07_+SUMIF('SG08'!$B:$B,$B18,'SG08'!K:K)*SG08_+SUMIF('SG09'!$B:$B,$B18,'SG09'!K:K)*SG09_+SUMIF('SG10'!$B:$B,$B18,'SG10'!K:K)*SG10_+SUMIF('SG11'!$B:$B,$B18,'SG11'!K:K)*SG11_+SUMIF('SG12'!$B:$B,$B18,'SG12'!K:K)*SG12_+SUMIF('SG13'!$B:$B,$B18,'SG13'!K:K)*SG13_+SUMIF('SG14'!$B:$B,$B18,'SG14'!K:K)*SG14_+SUMIF('SG15'!$B:$B,$B18,'SG15'!K:K)*SG15_) -> 1264804.6 | L18: =(SUMIF('SG01'!$B:$B,$B18,'SG01'!L:L)*SG01_+SUMIF('SG02'!$B:$B,$B18,'SG02'!L:L)*SG02_+SUMIF('SG03'!$B:$B,$B18,'SG03'!L:L)*SG03_+SUMIF('SG04'!$B:$B,$B18,'SG04'!L:L)*SG04_+SUMIF('SG05'!$B:$B,$B18,'SG05'!L:L)*SG05_+SUMIF('SG06'!$B:$B,$B18,'SG06'!L:L)*SG06_+SUMIF('SG07'!$B:$B,$B18,'SG07'!L:L)*SG07_+SUMIF('SG08'!$B:$B,$B18,'SG08'!L:L)*SG08_+SUMIF('SG09'!$B:$B,$B18,'SG09'!L:L)*SG09_+SUMIF('SG10'!$B:$B,$B18,'SG10'!L:L)*SG10_+SUMIF('SG11'!$B:$B,$B18,'SG11'!L:L)*SG11_+SUMIF('SG12'!$B:$B,$B18,'SG12'!L:L)*SG12_+SUMIF('SG13'!$B:$B,$B18,'SG13'!L:L)*SG13_+SUMIF('SG14'!$B:$B,$B18,'SG14'!L:L)*SG14_+SUMIF('SG15'!$B:$B,$B18,'SG15'!L:L)*SG15_) -> 5070000 | M18: =L18-K18 -> 3805195.4 | N18: =K18/L18 -> 0.24946835 | O18: =L18/L$10 -> 0.0032697801 | P18: =M18/M$10 -> 0.0036985077 | Q18: =I18/I$10 -> 0.0051706952 | R18: =I18/$K$5*100 -> 2.2474953 | S18: =R18*T$5 -> 6.6030231 | T18: =IFERROR(S18*G18,0) -> 403341.29 | V18: =IF(B18<>"",IFERROR(IF($I18>=$X$10,"High","Low"),""),"") -> Low | W18: =IF(B18<>"",IFERROR(IF($L18>=$X$12,"High","Low"),""),"") -> High | X18: =IF(B18<>"",IFERROR(IF(AND(V18="high",W18="high"),"Star",IF(AND(V18="low",W18="high"),"Puzzle",(IF(AND(V18="high",W18="low"),"Horse","Dog")))),""),"") -> Puzzle | AB18: DUPC.GSG | AC18: ĐỒ UỐNG PHA CHẾ | AD18: =VLOOKUP(AB18,$B:$M,11,0) -> 57601000 | AE18: =AD18/AE$5 -> 15597.346 | AF18: =VLOOKUP(AB18,$B:$R,8,0) -> 1205 | AG18: =AF18/$AE$5*100 -> 32.629299 | AH18: =(SUMIF('SG01'!$AA:$AA,$AB18,'SG01'!AG:AG)*SG01_+SUMIF('SG02'!$AA:$AA,$AB18,'SG02'!AG:AG)*SG02_+SUMIF('SG03'!$AA:$AA,$AB18,'SG03'!AG:AG)*SG03_+SUMIF('SG04'!$AA:$AA,$AB18,'SG04'!AG:AG)*SG04_+SUMIF('SG05'!$AA:$AA,$AB18,'SG05'!AG:AG)*SG05_+SUMIF('SG06'!$AA:$AA,$AB18,'SG06'!AG:AG)*SG06_+SUMIF('SG07'!$AA:$AA,$AB18,'SG07'!AG:AG)*SG07_+SUMIF('SG08'!$AA:$AA,$AB18,'SG08'!AG:AG)*SG08_+SUMIF('SG09'!$AA:$AA,$AB18,'SG09'!AG:AG)*SG09_+SUMIF('SG10'!$AA:$AA,$AB18,'SG10'!AG:AG)*SG10_+SUMIF('SG11'!$AA:$AA,$AB18,'SG11'!AG:AG)*SG11_+SUMIF('SG12'!$AA:$AA,$AB18,'SG12'!AG:AG)*SG12_+SUMIF('SG13'!$AA:$AA,$AB18,'SG13'!AG:AG)*SG13_+SUMIF('SG14'!$AA:$AA,$AB18,'SG14'!AG:AG)*SG14_+SUMIF('SG15'!$AA:$AA,$AB18,'SG15'!AG:AG)*SG15_) -> 54516000 | AI18: =AH18/AI$5 -> 15483.101 | AJ18: =(SUMIF('SG01'!$AA:$AA,$AB18,'SG01'!AI:AI)*SG01_+SUMIF('SG02'!$AA:$AA,$AB18,'SG02'!AI:AI)*SG02_+SUMIF('SG03'!$AA:$AA,$AB18,'SG03'!AI:AI)*SG03_+SUMIF('SG04'!$AA:$AA,$AB18,'SG04'!AI:AI)*SG04_+SUMIF('SG05'!$AA:$AA,$AB18,'SG05'!AI:AI)*SG05_+SUMIF('SG06'!$AA:$AA,$AB18,'SG06'!AI:AI)*SG06_+SUMIF('SG07'!$AA:$AA,$AB18,'SG07'!AI:AI)*SG07_+SUMIF('SG08'!$AA:$AA,$AB18,'SG08'!AI:AI)*SG08_+SUMIF('SG09'!$AA:$AA,$AB18,'SG09'!AI:AI)*SG09_+SUMIF('SG10'!$AA:$AA,$AB18,'SG10'!AI:AI)*SG10_+SUMIF('SG11'!$AA:$AA,$AB18,'SG11'!AI:AI)*SG11_+SUMIF('SG12'!$AA:$AA,$AB18,'SG12'!AI:AI)*SG12_+SUMIF('SG13'!$AA:$AA,$AB18,'SG13'!AI:AI)*SG13_+SUMIF('SG14'!$AA:$AA,$AB18,'SG14'!AI:AI)*SG14_+SUMIF('SG15'!$AA:$AA,$AB18,'SG15'!AI:AI)*SG15_) -> 1140 | AK18: =AJ18/$AI$5*100 -> 32.377166 | AL18: =AE18-AI18 -> 114.24494 | AM18: =AG18-AK18 -> 0.2521331
A19: 2 | B19: GSKVI005 | C19: =VLOOKUP(B19,'SG02'!$B:$E,2,0) -> Rau Salad Hải Sản | E19: =VLOOKUP(B19,'SG01'!$B:$E,4,0) -> Phần | F19: =K19/I19 -> 34202.473 | G19: =L19/I19 -> 123125 | H19: =G19-F19 -> 88922.527 | I19: =(SUMIF('SG01'!$B:$B,$B19,'SG01'!I:I)*SG01_+SUMIF('SG02'!$B:$B,$B19,'SG02'!I:I)*SG02_+SUMIF('SG03'!$B:$B,$B19,'SG03'!I:I)*SG03_+SUMIF('SG04'!$B:$B,$B19,'SG04'!I:I)*SG04_+SUMIF('SG05'!$B:$B,$B19,'SG05'!I:I)*SG05_+SUMIF('SG06'!$B:$B,$B19,'SG06'!I:I)*SG06_+SUMIF('SG07'!$B:$B,$B19,'SG07'!I:I)*SG07_+SUMIF('SG08'!$B:$B,$B19,'SG08'!I:I)*SG08_+SUMIF('SG09'!$B:$B,$B19,'SG09'!I:I)*SG09_+SUMIF('SG10'!$B:$B,$B19,'SG10'!I:I)*SG10_+SUMIF('SG11'!$B:$B,$B19,'SG11'!I:I)*SG11_+SUMIF('SG12'!$B:$B,$B19,'SG12'!I:I)*SG12_+SUMIF('SG13'!$B:$B,$B19,'SG13'!I:I)*SG13_+SUMIF('SG14'!$B:$B,$B19,'SG14'!I:I)*SG14_+SUMIF('SG15'!$B:$B,$B19,'SG15'!I:I)*SG15_) -> 48 | K19: =(SUMIF('SG01'!$B:$B,$B19,'SG01'!K:K)*SG01_+SUMIF('SG02'!$B:$B,$B19,'SG02'!K:K)*SG02_+SUMIF('SG03'!$B:$B,$B19,'SG03'!K:K)*SG03_+SUMIF('SG04'!$B:$B,$B19,'SG04'!K:K)*SG04_+SUMIF('SG05'!$B:$B,$B19,'SG05'!K:K)*SG05_+SUMIF('SG06'!$B:$B,$B19,'SG06'!K:K)*SG06_+SUMIF('SG07'!$B:$B,$B19,'SG07'!K:K)*SG07_+SUMIF('SG08'!$B:$B,$B19,'SG08'!K:K)*SG08_+SUMIF('SG09'!$B:$B,$B19,'SG09'!K:K)*SG09_+SUMIF('SG10'!$B:$B,$B19,'SG10'!K:K)*SG10_+SUMIF('SG11'!$B:$B,$B19,'SG11'!K:K)*SG11_+SUMIF('SG12'!$B:$B,$B19,'SG12'!K:K)*SG12_+SUMIF('SG13'!$B:$B,$B19,'SG13'!K:K)*SG13_+SUMIF('SG14'!$B:$B,$B19,'SG14'!K:K)*SG14_+SUMIF('SG15'!$B:$B,$B19,'SG15'!K:K)*SG15_) -> 1641718.7 | L19: =(SUMIF('SG01'!$B:$B,$B19,'SG01'!L:L)*SG01_+SUMIF('SG02'!$B:$B,$B19,'SG02'!L:L)*SG02_+SUMIF('SG03'!$B:$B,$B19,'SG03'!L:L)*SG03_+SUMIF('SG04'!$B:$B,$B19,'SG04'!L:L)*SG04_+SUMIF('SG05'!$B:$B,$B19,'SG05'!L:L)*SG05_+SUMIF('SG06'!$B:$B,$B19,'SG06'!L:L)*SG06_+SUMIF('SG07'!$B:$B,$B19,'SG07'!L:L)*SG07_+SUMIF('SG08'!$B:$B,$B19,'SG08'!L:L)*SG08_+SUMIF('SG09'!$B:$B,$B19,'SG09'!L:L)*SG09_+SUMIF('SG10'!$B:$B,$B19,'SG10'!L:L)*SG10_+SUMIF('SG11'!$B:$B,$B19,'SG11'!L:L)*SG11_+SUMIF('SG12'!$B:$B,$B19,'SG12'!L:L)*SG12_+SUMIF('SG13'!$B:$B,$B19,'SG13'!L:L)*SG13_+SUMIF('SG14'!$B:$B,$B19,'SG14'!L:L)*SG14_+SUMIF('SG15'!$B:$B,$B19,'SG15'!L:L)*SG15_) -> 5910000 | M19: =L19-K19 -> 4268281.3 | N19: =K19/L19 -> 0.27778658 | O19: =L19/L$10 -> 0.0038115188 | P19: =M19/M$10 -> 0.0041486098 | Q19: =I19/I$10 -> 0.0029902816 | R19: =I19/$K$5*100 -> 1.2997563 | S19: =R19*T$5 -> 3.8186158 | T19: =IFERROR(S19*G19,0) -> 470167.06 | V19: =IF(B19<>"",IFERROR(IF($I19>=$X$10,"High","Low"),""),"") -> Low | W19: =IF(B19<>"",IFERROR(IF($L19>=$X$12,"High","Low"),""),"") -> High | X19: =IF(B19<>"",IFERROR(IF(AND(V19="high",W19="high"),"Star",IF(AND(V19="low",W19="high"),"Puzzle",(IF(AND(V19="high",W19="low"),"Horse","Dog")))),""),"") -> Puzzle | AB19: CPL.BAR | AC19: CHI PHÍ QUẦY LINE BAR | AD19: =VLOOKUP(AB19,$B:$M,11,0) -> 1350000 | AE19: =AD19/AE$5 -> 365.55646 | AF19: =VLOOKUP(AB19,$B:$R,8,0) -> 1362 | AG19: =AF19/$AE$5*100 -> 36.880585 | AH19: =(SUMIF('SG01'!$AA:$AA,$AB19,'SG01'!AG:AG)*SG01_+SUMIF('SG02'!$AA:$AA,$AB19,'SG02'!AG:AG)*SG02_+SUMIF('SG03'!$AA:$AA,$AB19,'SG03'!AG:AG)*SG03_+SUMIF('SG04'!$AA:$AA,$AB19,'SG04'!AG:AG)*SG04_+SUMIF('SG05'!$AA:$AA,$AB19,'SG05'!AG:AG)*SG05_+SUMIF('SG06'!$AA:$AA,$AB19,'SG06'!AG:AG)*SG06_+SUMIF('SG07'!$AA:$AA,$AB19,'SG07'!AG:AG)*SG07_+SUMIF('SG08'!$AA:$AA,$AB19,'SG08'!AG:AG)*SG08_+SUMIF('SG09'!$AA:$AA,$AB19,'SG09'!AG:AG)*SG09_+SUMIF('SG10'!$AA:$AA,$AB19,'SG10'!AG:AG)*SG10_+SUMIF('SG11'!$AA:$AA,$AB19,'SG11'!AG:AG)*SG11_+SUMIF('SG12'!$AA:$AA,$AB19,'SG12'!AG:AG)*SG12_+SUMIF('SG13'!$AA:$AA,$AB19,'SG13'!AG:AG)*SG13_+SUMIF('SG14'!$AA:$AA,$AB19,'SG14'!AG:AG)*SG14_+SUMIF('SG15'!$AA:$AA,$AB19,'SG15'!AG:AG)*SG15_) -> 1310000 | AI19: =AH19/AI$5 -> 372.05339 | AJ19: =(SUMIF('SG01'!$AA:$AA,$AB19,'SG01'!AI:AI)*SG01_+SUMIF('SG02'!$AA:$AA,$AB19,'SG02'!AI:AI)*SG02_+SUMIF('SG03'!$AA:$AA,$AB19,'SG03'!AI:AI)*SG03_+SUMIF('SG04'!$AA:$AA,$AB19,'SG04'!AI:AI)*SG04_+SUMIF('SG05'!$AA:$AA,$AB19,'SG05'!AI:AI)*SG05_+SUMIF('SG06'!$AA:$AA,$AB19,'SG06'!AI:AI)*SG06_+SUMIF('SG07'!$AA:$AA,$AB19,'SG07'!AI:AI)*SG07_+SUMIF('SG08'!$AA:$AA,$AB19,'SG08'!AI:AI)*SG08_+SUMIF('SG09'!$AA:$AA,$AB19,'SG09'!AI:AI)*SG09_+SUMIF('SG10'!$AA:$AA,$AB19,'SG10'!AI:AI)*SG10_+SUMIF('SG11'!$AA:$AA,$AB19,'SG11'!AI:AI)*SG11_+SUMIF('SG12'!$AA:$AA,$AB19,'SG12'!AI:AI)*SG12_+SUMIF('SG13'!$AA:$AA,$AB19,'SG13'!AI:AI)*SG13_+SUMIF('SG14'!$AA:$AA,$AB19,'SG14'!AI:AI)*SG14_+SUMIF('SG15'!$AA:$AA,$AB19,'SG15'!AI:AI)*SG15_) -> 1293 | AK19: =AJ19/$AI$5*100 -> 36.722522 | AL19: =AE19-AI19 -> -6.4969358 | AM19: =AG19-AK19 -> 0.15806288
A20: 3 | B20: GSKVI006 | C20: =VLOOKUP(B20,'SG02'!$B:$E,2,0) -> Rau Salad Rong Biển | E20: =VLOOKUP(B20,'SG01'!$B:$E,4,0) -> Phần | F20: =K20/I20 -> 27302.912 | G20: =L20/I20 -> 81421.053 | H20: =G20-F20 -> 54118.141 | I20: =(SUMIF('SG01'!$B:$B,$B20,'SG01'!I:I)*SG01_+SUMIF('SG02'!$B:$B,$B20,'SG02'!I:I)*SG02_+SUMIF('SG03'!$B:$B,$B20,'SG03'!I:I)*SG03_+SUMIF('SG04'!$B:$B,$B20,'SG04'!I:I)*SG04_+SUMIF('SG05'!$B:$B,$B20,'SG05'!I:I)*SG05_+SUMIF('SG06'!$B:$B,$B20,'SG06'!I:I)*SG06_+SUMIF('SG07'!$B:$B,$B20,'SG07'!I:I)*SG07_+SUMIF('SG08'!$B:$B,$B20,'SG08'!I:I)*SG08_+SUMIF('SG09'!$B:$B,$B20,'SG09'!I:I)*SG09_+SUMIF('SG10'!$B:$B,$B20,'SG10'!I:I)*SG10_+SUMIF('SG11'!$B:$B,$B20,'SG11'!I:I)*SG11_+SUMIF('SG12'!$B:$B,$B20,'SG12'!I:I)*SG12_+SUMIF('SG13'!$B:$B,$B20,'SG13'!I:I)*SG13_+SUMIF('SG14'!$B:$B,$B20,'SG14'!I:I)*SG14_+SUMIF('SG15'!$B:$B,$B20,'SG15'!I:I)*SG15_) -> 38 | K20: =(SUMIF('SG01'!$B:$B,$B20,'SG01'!K:K)*SG01_+SUMIF('SG02'!$B:$B,$B20,'SG02'!K:K)*SG02_+SUMIF('SG03'!$B:$B,$B20,'SG03'!K:K)*SG03_+SUMIF('SG04'!$B:$B,$B20,'SG04'!K:K)*SG04_+SUMIF('SG05'!$B:$B,$B20,'SG05'!K:K)*SG05_+SUMIF('SG06'!$B:$B,$B20,'SG06'!K:K)*SG06_+SUMIF('SG07'!$B:$B,$B20,'SG07'!K:K)*SG07_+SUMIF('SG08'!$B:$B,$B20,'SG08'!K:K)*SG08_+SUMIF('SG09'!$B:$B,$B20,'SG09'!K:K)*SG09_+SUMIF('SG10'!$B:$B,$B20,'SG10'!K:K)*SG10_+SUMIF('SG11'!$B:$B,$B20,'SG11'!K:K)*SG11_+SUMIF('SG12'!$B:$B,$B20,'SG12'!K:K)*SG12_+SUMIF('SG13'!$B:$B,$B20,'SG13'!K:K)*SG13_+SUMIF('SG14'!$B:$B,$B20,'SG14'!K:K)*SG14_+SUMIF('SG15'!$B:$B,$B20,'SG15'!K:K)*SG15_) -> 1037510.6 | L20: =(SUMIF('SG01'!$B:$B,$B20,'SG01'!L:L)*SG01_+SUMIF('SG02'!$B:$B,$B20,'SG02'!L:L)*SG02_+SUMIF('SG03'!$B:$B,$B20,'SG03'!L:L)*SG03_+SUMIF('SG04'!$B:$B,$B20,'SG04'!L:L)*SG04_+SUMIF('SG05'!$B:$B,$B20,'SG05'!L:L)*SG05_+SUMIF('SG06'!$B:$B,$B20,'SG06'!L:L)*SG06_+SUMIF('SG07'!$B:$B,$B20,'SG07'!L:L)*SG07_+SUMIF('SG08'!$B:$B,$B20,'SG08'!L:L)*SG08_+SUMIF('SG09'!$B:$B,$B20,'SG09'!L:L)*SG09_+SUMIF('SG10'!$B:$B,$B20,'SG10'!L:L)*SG10_+SUMIF('SG11'!$B:$B,$B20,'SG11'!L:L)*SG11_+SUMIF('SG12'!$B:$B,$B20,'SG12'!L:L)*SG12_+SUMIF('SG13'!$B:$B,$B20,'SG13'!L:L)*SG13_+SUMIF('SG14'!$B:$B,$B20,'SG14'!L:L)*SG14_+SUMIF('SG15'!$B:$B,$B20,'SG15'!L:L)*SG15_) -> 3094000 | M20: =L20-K20 -> 2056489.4 | N20: =K20/L20 -> 0.33532988 | O20: =L20/L$10 -> 0.0019954042 | P20: =M20/M$10 -> 0.0019988308 | Q20: =I20/I$10 -> 0.0023673063 | R20: =I20/$K$5*100 -> 1.0289737 | S20: =R20*T$5 -> 3.0230708 | T20: =IFERROR(S20*G20,0) -> 246141.61 | V20: =IF(B20<>"",IFERROR(IF($I20>=$X$10,"High","Low"),""),"") -> Low | W20: =IF(B20<>"",IFERROR(IF($L20>=$X$12,"High","Low"),""),"") -> High | X20: =IF(B20<>"",IFERROR(IF(AND(V20="high",W20="high"),"Star",IF(AND(V20="low",W20="high"),"Puzzle",(IF(AND(V20="high",W20="low"),"Horse","Dog")))),""),"") -> Puzzle | AB20: DVU.GSG | AC20: DỊCH VỤ/SERVICE | AD20: =VLOOKUP(AB20,$B:$M,11,0) -> 9489000 | AE20: =AD20/AE$5 -> 2569.4557 | AF20: =VLOOKUP(AB20,$B:$R,8,0) -> 3163 | AG20: =AF20/$AE$5*100 -> 85.648524 | AH20: =(SUMIF('SG01'!$AA:$AA,$AB20,'SG01'!AG:AG)*SG01_+SUMIF('SG02'!$AA:$AA,$AB20,'SG02'!AG:AG)*SG02_+SUMIF('SG03'!$AA:$AA,$AB20,'SG03'!AG:AG)*SG03_+SUMIF('SG04'!$AA:$AA,$AB20,'SG04'!AG:AG)*SG04_+SUMIF('SG05'!$AA:$AA,$AB20,'SG05'!AG:AG)*SG05_+SUMIF('SG06'!$AA:$AA,$AB20,'SG06'!AG:AG)*SG06_+SUMIF('SG07'!$AA:$AA,$AB20,'SG07'!AG:AG)*SG07_+SUMIF('SG08'!$AA:$AA,$AB20,'SG08'!AG:AG)*SG08_+SUMIF('SG09'!$AA:$AA,$AB20,'SG09'!AG:AG)*SG09_+SUMIF('SG10'!$AA:$AA,$AB20,'SG10'!AG:AG)*SG10_+SUMIF('SG11'!$AA:$AA,$AB20,'SG11'!AG:AG)*SG11_+SUMIF('SG12'!$AA:$AA,$AB20,'SG12'!AG:AG)*SG12_+SUMIF('SG13'!$AA:$AA,$AB20,'SG13'!AG:AG)*SG13_+SUMIF('SG14'!$AA:$AA,$AB20,'SG14'!AG:AG)*SG14_+SUMIF('SG15'!$AA:$AA,$AB20,'SG15'!AG:AG)*SG15_) -> 9081000 | AI20: =AH20/AI$5 -> 2579.0968 | AJ20: =(SUMIF('SG01'!$AA:$AA,$AB20,'SG01'!AI:AI)*SG01_+SUMIF('SG02'!$AA:$AA,$AB20,'SG02'!AI:AI)*SG02_+SUMIF('SG03'!$AA:$AA,$AB20,'SG03'!AI:AI)*SG03_+SUMIF('SG04'!$AA:$AA,$AB20,'SG04'!AI:AI)*SG04_+SUMIF('SG05'!$AA:$AA,$AB20,'SG05'!AI:AI)*SG05_+SUMIF('SG06'!$AA:$AA,$AB20,'SG06'!AI:AI)*SG06_+SUMIF('SG07'!$AA:$AA,$AB20,'SG07'!AI:AI)*SG07_+SUMIF('SG08'!$AA:$AA,$AB20,'SG08'!AI:AI)*SG08_+SUMIF('SG09'!$AA:$AA,$AB20,'SG09'!AI:AI)*SG09_+SUMIF('SG10'!$AA:$AA,$AB20,'SG10'!AI:AI)*SG10_+SUMIF('SG11'!$AA:$AA,$AB20,'SG11'!AI:AI)*SG11_+SUMIF('SG12'!$AA:$AA,$AB20,'SG12'!AI:AI)*SG12_+SUMIF('SG13'!$AA:$AA,$AB20,'SG13'!AI:AI)*SG13_+SUMIF('SG14'!$AA:$AA,$AB20,'SG14'!AI:AI)*SG14_+SUMIF('SG15'!$AA:$AA,$AB20,'SG15'!AI:AI)*SG15_) -> 3027 | AK20: =AJ20/$AI$5*100 -> 85.969895 | AL20: =AE20-AI20 -> -9.6411204 | AM20: =AG20-AK20 -> -0.32137068
A21: =+A20+1 -> 4 | B21: GSKVI007 | C21: =VLOOKUP(B21,'SG02'!$B:$E,2,0) -> Rau Salad Bơ Xốt Mè Rang | E21: =VLOOKUP(B21,'SG01'!$B:$E,4,0) -> Phần | F21: =K21/I21 -> 20205.796 | G21: =L21/I21 -> 81594.937 | H21: =G21-F21 -> 61389.14 | I21: =(SUMIF('SG01'!$B:$B,$B21,'SG01'!I:I)*SG01_+SUMIF('SG02'!$B:$B,$B21,'SG02'!I:I)*SG02_+SUMIF('SG03'!$B:$B,$B21,'SG03'!I:I)*SG03_+SUMIF('SG04'!$B:$B,$B21,'SG04'!I:I)*SG04_+SUMIF('SG05'!$B:$B,$B21,'SG05'!I:I)*SG05_+SUMIF('SG06'!$B:$B,$B21,'SG06'!I:I)*SG06_+SUMIF('SG07'!$B:$B,$B21,'SG07'!I:I)*SG07_+SUMIF('SG08'!$B:$B,$B21,'SG08'!I:I)*SG08_+SUMIF('SG09'!$B:$B,$B21,'SG09'!I:I)*SG09_+SUMIF('SG10'!$B:$B,$B21,'SG10'!I:I)*SG10_+SUMIF('SG11'!$B:$B,$B21,'SG11'!I:I)*SG11_+SUMIF('SG12'!$B:$B,$B21,'SG12'!I:I)*SG12_+SUMIF('SG13'!$B:$B,$B21,'SG13'!I:I)*SG13_+SUMIF('SG14'!$B:$B,$B21,'SG14'!I:I)*SG14_+SUMIF('SG15'!$B:$B,$B21,'SG15'!I:I)*SG15_) -> 79 | K21: =(SUMIF('SG01'!$B:$B,$B21,'SG01'!K:K)*SG01_+SUMIF('SG02'!$B:$B,$B21,'SG02'!K:K)*SG02_+SUMIF('SG03'!$B:$B,$B21,'SG03'!K:K)*SG03_+SUMIF('SG04'!$B:$B,$B21,'SG04'!K:K)*SG04_+SUMIF('SG05'!$B:$B,$B21,'SG05'!K:K)*SG05_+SUMIF('SG06'!$B:$B,$B21,'SG06'!K:K)*SG06_+SUMIF('SG07'!$B:$B,$B21,'SG07'!K:K)*SG07_+SUMIF('SG08'!$B:$B,$B21,'SG08'!K:K)*SG08_+SUMIF('SG09'!$B:$B,$B21,'SG09'!K:K)*SG09_+SUMIF('SG10'!$B:$B,$B21,'SG10'!K:K)*SG10_+SUMIF('SG11'!$B:$B,$B21,'SG11'!K:K)*SG11_+SUMIF('SG12'!$B:$B,$B21,'SG12'!K:K)*SG12_+SUMIF('SG13'!$B:$B,$B21,'SG13'!K:K)*SG13_+SUMIF('SG14'!$B:$B,$B21,'SG14'!K:K)*SG14_+SUMIF('SG15'!$B:$B,$B21,'SG15'!K:K)*SG15_) -> 1596257.9 | L21: =(SUMIF('SG01'!$B:$B,$B21,'SG01'!L:L)*SG01_+SUMIF('SG02'!$B:$B,$B21,'SG02'!L:L)*SG02_+SUMIF('SG03'!$B:$B,$B21,'SG03'!L:L)*SG03_+SUMIF('SG04'!$B:$B,$B21,'SG04'!L:L)*SG04_+SUMIF('SG05'!$B:$B,$B21,'SG05'!L:L)*SG05_+SUMIF('SG06'!$B:$B,$B21,'SG06'!L:L)*SG06_+SUMIF('SG07'!$B:$B,$B21,'SG07'!L:L)*SG07_+SUMIF('SG08'!$B:$B,$B21,'SG08'!L:L)*SG08_+SUMIF('SG09'!$B:$B,$B21,'SG09'!L:L)*SG09_+SUMIF('SG10'!$B:$B,$B21,'SG10'!L:L)*SG10_+SUMIF('SG11'!$B:$B,$B21,'SG11'!L:L)*SG11_+SUMIF('SG12'!$B:$B,$B21,'SG12'!L:L)*SG12_+SUMIF('SG13'!$B:$B,$B21,'SG13'!L:L)*SG13_+SUMIF('SG14'!$B:$B,$B21,'SG14'!L:L)*SG14_+SUMIF('SG15'!$B:$B,$B21,'SG15'!L:L)*SG15_) -> 6446000 | M21: =L21-K21 -> 4849742.1 | N21: =K21/L21 -> 0.24763542 | O21: =L21/L$10 -> 0.0041571997 | P21: =M21/M$10 -> 0.004713768 | Q21: =I21/I$10 -> 0.0049215051 | R21: =I21/$K$5*100 -> 2.1391822 | S21: =R21*T$5 -> 6.2848051 | T21: =IFERROR(S21*G21,0) -> 512808.27 | V21: =IF(B21<>"",IFERROR(IF($I21>=$X$10,"High","Low"),""),"") -> Low | W21: =IF(B21<>"",IFERROR(IF($L21>=$X$12,"High","Low"),""),"") -> High | X21: =IF(B21<>"",IFERROR(IF(AND(V21="high",W21="high"),"Star",IF(AND(V21="low",W21="high"),"Puzzle",(IF(AND(V21="high",W21="low"),"Horse","Dog")))),""),"") -> Puzzle
A22: =+A21+1 -> 5 | B22: GSKVI008 | C22: =VLOOKUP(B22,'SG02'!$B:$E,2,0) -> Rau Củ Muối Chua Ngọt | E22: =VLOOKUP(B22,'SG01'!$B:$E,4,0) -> Phần | F22: =K22/I22 -> 7147.2 | G22: =L22/I22 -> 51666.667 | H22: =G22-F22 -> 44519.467 | I22: =(SUMIF('SG01'!$B:$B,$B22,'SG01'!I:I)*SG01_+SUMIF('SG02'!$B:$B,$B22,'SG02'!I:I)*SG02_+SUMIF('SG03'!$B:$B,$B22,'SG03'!I:I)*SG03_+SUMIF('SG04'!$B:$B,$B22,'SG04'!I:I)*SG04_+SUMIF('SG05'!$B:$B,$B22,'SG05'!I:I)*SG05_+SUMIF('SG06'!$B:$B,$B22,'SG06'!I:I)*SG06_+SUMIF('SG07'!$B:$B,$B22,'SG07'!I:I)*SG07_+SUMIF('SG08'!$B:$B,$B22,'SG08'!I:I)*SG08_+SUMIF('SG09'!$B:$B,$B22,'SG09'!I:I)*SG09_+SUMIF('SG10'!$B:$B,$B22,'SG10'!I:I)*SG10_+SUMIF('SG11'!$B:$B,$B22,'SG11'!I:I)*SG11_+SUMIF('SG12'!$B:$B,$B22,'SG12'!I:I)*SG12_+SUMIF('SG13'!$B:$B,$B22,'SG13'!I:I)*SG13_+SUMIF('SG14'!$B:$B,$B22,'SG14'!I:I)*SG14_+SUMIF('SG15'!$B:$B,$B22,'SG15'!I:I)*SG15_) -> 12 | K22: =(SUMIF('SG01'!$B:$B,$B22,'SG01'!K:K)*SG01_+SUMIF('SG02'!$B:$B,$B22,'SG02'!K:K)*SG02_+SUMIF('SG03'!$B:$B,$B22,'SG03'!K:K)*SG03_+SUMIF('SG04'!$B:$B,$B22,'SG04'!K:K)*SG04_+SUMIF('SG05'!$B:$B,$B22,'SG05'!K:K)*SG05_+SUMIF('SG06'!$B:$B,$B22,'SG06'!K:K)*SG06_+SUMIF('SG07'!$B:$B,$B22,'SG07'!K:K)*SG07_+SUMIF('SG08'!$B:$B,$B22,'SG08'!K:K)*SG08_+SUMIF('SG09'!$B:$B,$B22,'SG09'!K:K)*SG09_+SUMIF('SG10'!$B:$B,$B22,'SG10'!K:K)*SG10_+SUMIF('SG11'!$B:$B,$B22,'SG11'!K:K)*SG11_+SUMIF('SG12'!$B:$B,$B22,'SG12'!K:K)*SG12_+SUMIF('SG13'!$B:$B,$B22,'SG13'!K:K)*SG13_+SUMIF('SG14'!$B:$B,$B22,'SG14'!K:K)*SG14_+SUMIF('SG15'!$B:$B,$B22,'SG15'!K:K)*SG15_) -> 85766.4 | L22: =(SUMIF('SG01'!$B:$B,$B22,'SG01'!L:L)*SG01_+SUMIF('SG02'!$B:$B,$B22,'SG02'!L:L)*SG02_+SUMIF('SG03'!$B:$B,$B22,'SG03'!L:L)*SG03_+SUMIF('SG04'!$B:$B,$B22,'SG04'!L:L)*SG04_+SUMIF('SG05'!$B:$B,$B22,'SG05'!L:L)*SG05_+SUMIF('SG06'!$B:$B,$B22,'SG06'!L:L)*SG06_+SUMIF('SG07'!$B:$B,$B22,'SG07'!L:L)*SG07_+SUMIF('SG08'!$B:$B,$B22,'SG08'!L:L)*SG08_+SUMIF('SG09'!$B:$B,$B22,'SG09'!L:L)*SG09_+SUMIF('SG10'!$B:$B,$B22,'SG10'!L:L)*SG10_+SUMIF('SG11'!$B:$B,$B22,'SG11'!L:L)*SG11_+SUMIF('SG12'!$B:$B,$B22,'SG12'!L:L)*SG12_+SUMIF('SG13'!$B:$B,$B22,'SG13'!L:L)*SG13_+SUMIF('SG14'!$B:$B,$B22,'SG14'!L:L)*SG14_+SUMIF('SG15'!$B:$B,$B22,'SG15'!L:L)*SG15_) -> 620000 | M22: =L22-K22 -> 534233.6 | N22: =K22/L22 -> 0.1383329 | O22: =L22/L$10 -> 0.00039985476 | P22: =M22/M$10 -> 0.00051925509 | Q22: =I22/I$10 -> 0.0007475704 | R22: =I22/$K$5*100 -> 0.32493907 | S22: =R22*T$5 -> 0.95465394 | T22: =IFERROR(S22*G22,0) -> 49323.787 | V22: =IF(B22<>"",IFERROR(IF($I22>=$X$10,"High","Low"),""),"") -> Low | W22: =IF(B22<>"",IFERROR(IF($L22>=$X$12,"High","Low"),""),"") -> Low | X22: =IF(B22<>"",IFERROR(IF(AND(V22="high",W22="high"),"Star",IF(AND(V22="low",W22="high"),"Puzzle",(IF(AND(V22="high",W22="low"),"Horse","Dog")))),""),"") -> Dog
A23: =+A22+1 -> 6 | B23: GSKVI009 | C23: =VLOOKUP(B23,'SG02'!$B:$E,2,0) -> Bạch Quả | E23: =VLOOKUP(B23,'SG01'!$B:$E,4,0) -> Phần | F23: =K23/I23 -> 11788 | G23: =L23/I23 -> 39000 | H23: =G23-F23 -> 27212 | I23: =(SUMIF('SG01'!$B:$B,$B23,'SG01'!I:I)*SG01_+SUMIF('SG02'!$B:$B,$B23,'SG02'!I:I)*SG02_+SUMIF('SG03'!$B:$B,$B23,'SG03'!I:I)*SG03_+SUMIF('SG04'!$B:$B,$B23,'SG04'!I:I)*SG04_+SUMIF('SG05'!$B:$B,$B23,'SG05'!I:I)*SG05_+SUMIF('SG06'!$B:$B,$B23,'SG06'!I:I)*SG06_+SUMIF('SG07'!$B:$B,$B23,'SG07'!I:I)*SG07_+SUMIF('SG08'!$B:$B,$B23,'SG08'!I:I)*SG08_+SUMIF('SG09'!$B:$B,$B23,'SG09'!I:I)*SG09_+SUMIF('SG10'!$B:$B,$B23,'SG10'!I:I)*SG10_+SUMIF('SG11'!$B:$B,$B23,'SG11'!I:I)*SG11_+SUMIF('SG12'!$B:$B,$B23,'SG12'!I:I)*SG12_+SUMIF('SG13'!$B:$B,$B23,'SG13'!I:I)*SG13_+SUMIF('SG14'!$B:$B,$B23,'SG14'!I:I)*SG14_+SUMIF('SG15'!$B:$B,$B23,'SG15'!I:I)*SG15_) -> 22 | K23: =(SUMIF('SG01'!$B:$B,$B23,'SG01'!K:K)*SG01_+SUMIF('SG02'!$B:$B,$B23,'SG02'!K:K)*SG02_+SUMIF('SG03'!$B:$B,$B23,'SG03'!K:K)*SG03_+SUMIF('SG04'!$B:$B,$B23,'SG04'!K:K)*SG04_+SUMIF('SG05'!$B:$B,$B23,'SG05'!K:K)*SG05_+SUMIF('SG06'!$B:$B,$B23,'SG06'!K:K)*SG06_+SUMIF('SG07'!$B:$B,$B23,'SG07'!K:K)*SG07_+SUMIF('SG08'!$B:$B,$B23,'SG08'!K:K)*SG08_+SUMIF('SG09'!$B:$B,$B23,'SG09'!K:K)*SG09_+SUMIF('SG10'!$B:$B,$B23,'SG10'!K:K)*SG10_+SUMIF('SG11'!$B:$B,$B23,'SG11'!K:K)*SG11_+SUMIF('SG12'!$B:$B,$B23,'SG12'!K:K)*SG12_+SUMIF('SG13'!$B:$B,$B23,'SG13'!K:K)*SG13_+SUMIF('SG14'!$B:$B,$B23,'SG14'!K:K)*SG14_+SUMIF('SG15'!$B:$B,$B23,'SG15'!K:K)*SG15_) -> 259336 | L23: =(SUMIF('SG01'!$B:$B,$B23,'SG01'!L:L)*SG01_+SUMIF('SG02'!$B:$B,$B23,'SG02'!L:L)*SG02_+SUMIF('SG03'!$B:$B,$B23,'SG03'!L:L)*SG03_+SUMIF('SG04'!$B:$B,$B23,'SG04'!L:L)*SG04_+SUMIF('SG05'!$B:$B,$B23,'SG05'!L:L)*SG05_+SUMIF('SG06'!$B:$B,$B23,'SG06'!L:L)*SG06_+SUMIF('SG07'!$B:$B,$B23,'SG07'!L:L)*SG07_+SUMIF('SG08'!$B:$B,$B23,'SG08'!L:L)*SG08_+SUMIF('SG09'!$B:$B,$B23,'SG09'!L:L)*SG09_+SUMIF('SG10'!$B:$B,$B23,'SG10'!L:L)*SG10_+SUMIF('SG11'!$B:$B,$B23,'SG11'!L:L)*SG11_+SUMIF('SG12'!$B:$B,$B23,'SG12'!L:L)*SG12_+SUMIF('SG13'!$B:$B,$B23,'SG13'!L:L)*SG13_+SUMIF('SG14'!$B:$B,$B23,'SG14'!L:L)*SG14_+SUMIF('SG15'!$B:$B,$B23,'SG15'!L:L)*SG15_) -> 858000 | M23: =L23-K23 -> 598664 | N23: =K23/L23 -> 0.30225641 | O23: =L23/L$10 -> 0.0005533474 | P23: =M23/M$10 -> 0.00058187903 | Q23: =I23/I$10 -> 0.0013705457 | R23: =I23/$K$5*100 -> 0.59572164 | S23: =R23*T$5 -> 1.7501989 | T23: =IFERROR(S23*G23,0) -> 68257.757 | V23: =IF(B23<>"",IFERROR(IF($I23>=$X$10,"High","Low"),""),"") -> Low | W23: =IF(B23<>"",IFERROR(IF($L23>=$X$12,"High","Low"),""),"") -> Low | X23: =IF(B23<>"",IFERROR(IF(AND(V23="high",W23="high"),"Star",IF(AND(V23="low",W23="high"),"Puzzle",(IF(AND(V23="high",W23="low"),"Horse","Dog")))),""),"") -> Dog
A24: =+A23+1 -> 7 | B24: GSKVI010 | C24: =VLOOKUP(B24,'SG02'!$B:$E,2,0) -> Đậu Nành Nhật | E24: =VLOOKUP(B24,'SG01'!$B:$E,4,0) -> Phần | F24: =K24/I24 -> 13625.134 | G24: =L24/I24 -> 50694.444 | H24: =G24-F24 -> 37069.31 | I24: =(SUMIF('SG01'!$B:$B,$B24,'SG01'!I:I)*SG01_+SUMIF('SG02'!$B:$B,$B24,'SG02'!I:I)*SG02_+SUMIF('SG03'!$B:$B,$B24,'SG03'!I:I)*SG03_+SUMIF('SG04'!$B:$B,$B24,'SG04'!I:I)*SG04_+SUMIF('SG05'!$B:$B,$B24,'SG05'!I:I)*SG05_+SUMIF('SG06'!$B:$B,$B24,'SG06'!I:I)*SG06_+SUMIF('SG07'!$B:$B,$B24,'SG07'!I:I)*SG07_+SUMIF('SG08'!$B:$B,$B24,'SG08'!I:I)*SG08_+SUMIF('SG09'!$B:$B,$B24,'SG09'!I:I)*SG09_+SUMIF('SG10'!$B:$B,$B24,'SG10'!I:I)*SG10_+SUMIF('SG11'!$B:$B,$B24,'SG11'!I:I)*SG11_+SUMIF('SG12'!$B:$B,$B24,'SG12'!I:I)*SG12_+SUMIF('SG13'!$B:$B,$B24,'SG13'!I:I)*SG13_+SUMIF('SG14'!$B:$B,$B24,'SG14'!I:I)*SG14_+SUMIF('SG15'!$B:$B,$B24,'SG15'!I:I)*SG15_) -> 72 | K24: =(SUMIF('SG01'!$B:$B,$B24,'SG01'!K:K)*SG01_+SUMIF('SG02'!$B:$B,$B24,'SG02'!K:K)*SG02_+SUMIF('SG03'!$B:$B,$B24,'SG03'!K:K)*SG03_+SUMIF('SG04'!$B:$B,$B24,'SG04'!K:K)*SG04_+SUMIF('SG05'!$B:$B,$B24,'SG05'!K:K)*SG05_+SUMIF('SG06'!$B:$B,$B24,'SG06'!K:K)*SG06_+SUMIF('SG07'!$B:$B,$B24,'SG07'!K:K)*SG07_+SUMIF('SG08'!$B:$B,$B24,'SG08'!K:K)*SG08_+SUMIF('SG09'!$B:$B,$B24,'SG09'!K:K)*SG09_+SUMIF('SG10'!$B:$B,$B24,'SG10'!K:K)*SG10_+SUMIF('SG11'!$B:$B,$B24,'SG11'!K:K)*SG11_+SUMIF('SG12'!$B:$B,$B24,'SG12'!K:K)*SG12_+SUMIF('SG13'!$B:$B,$B24,'SG13'!K:K)*SG13_+SUMIF('SG14'!$B:$B,$B24,'SG14'!K:K)*SG14_+SUMIF('SG15'!$B:$B,$B24,'SG15'!K:K)*SG15_) -> 981009.66 | L24: =(SUMIF('SG01'!$B:$B,$B24,'SG01'!L:L)*SG01_+SUMIF('SG02'!$B:$B,$B24,'SG02'!L:L)*SG02_+SUMIF('SG03'!$B:$B,$B24,'SG03'!L:L)*SG03_+SUMIF('SG04'!$B:$B,$B24,'SG04'!L:L)*SG04_+SUMIF('SG05'!$B:$B,$B24,'SG05'!L:L)*SG05_+SUMIF('SG06'!$B:$B,$B24,'SG06'!L:L)*SG06_+SUMIF('SG07'!$B:$B,$B24,'SG07'!L:L)*SG07_+SUMIF('SG08'!$B:$B,$B24,'SG08'!L:L)*SG08_+SUMIF('SG09'!$B:$B,$B24,'SG09'!L:L)*SG09_+SUMIF('SG10'!$B:$B,$B24,'SG10'!L:L)*SG10_+SUMIF('SG11'!$B:$B,$B24,'SG11'!L:L)*SG11_+SUMIF('SG12'!$B:$B,$B24,'SG12'!L:L)*SG12_+SUMIF('SG13'!$B:$B,$B24,'SG13'!L:L)*SG13_+SUMIF('SG14'!$B:$B,$B24,'SG14'!L:L)*SG14_+SUMIF('SG15'!$B:$B,$B24,'SG15'!L:L)*SG15_) -> 3650000 | M24: =L24-K24 -> 2668990.3 | N24: =K24/L24 -> 0.26876977 | O24: =L24/L$10 -> 0.0023539837 | P24: =M24/M$10 -> 0.0025941588 | Q24: =I24/I$10 -> 0.0044854224 | R24: =I24/$K$5*100 -> 1.9496344 | S24: =R24*T$5 -> 5.7279236 | T24: =IFERROR(S24*G24,0) -> 290373.91 | V24: =IF(B24<>"",IFERROR(IF($I24>=$X$10,"High","Low"),""),"") -> Low | W24: =IF(B24<>"",IFERROR(IF($L24>=$X$12,"High","Low"),""),"") -> High | X24: =IF(B24<>"",IFERROR(IF(AND(V24="high",W24="high"),"Star",IF(AND(V24="low",W24="high"),"Puzzle",(IF(AND(V24="high",W24="low"),"Horse","Dog")))),""),"") -> Puzzle
A25: =+A24+1 -> 8 | B25: GSKVI011 | C25: =VLOOKUP(B25,'SG02'!$B:$E,2,0) -> Bò Tái Xốt Ponzu | E25: =VLOOKUP(B25,'SG01'!$B:$E,4,0) -> Phần | F25: =K25/I25 -> #DIV/0! | G25: =L25/I25 -> #DIV/0! | H25: =G25-F25 -> #DIV/0! | I25: =(SUMIF('SG01'!$B:$B,$B25,'SG01'!I:I)*SG01_+SUMIF('SG02'!$B:$B,$B25,'SG02'!I:I)*SG02_+SUMIF('SG03'!$B:$B,$B25,'SG03'!I:I)*SG03_+SUMIF('SG04'!$B:$B,$B25,'SG04'!I:I)*SG04_+SUMIF('SG05'!$B:$B,$B25,'SG05'!I:I)*SG05_+SUMIF('SG06'!$B:$B,$B25,'SG06'!I:I)*SG06_+SUMIF('SG07'!$B:$B,$B25,'SG07'!I:I)*SG07_+SUMIF('SG08'!$B:$B,$B25,'SG08'!I:I)*SG08_+SUMIF('SG09'!$B:$B,$B25,'SG09'!I:I)*SG09_+SUMIF('SG10'!$B:$B,$B25,'SG10'!I:I)*SG10_+SUMIF('SG11'!$B:$B,$B25,'SG11'!I:I)*SG11_+SUMIF('SG12'!$B:$B,$B25,'SG12'!I:I)*SG12_+SUMIF('SG13'!$B:$B,$B25,'SG13'!I:I)*SG13_+SUMIF('SG14'!$B:$B,$B25,'SG14'!I:I)*SG14_+SUMIF('SG15'!$B:$B,$B25,'SG15'!I:I)*SG15_) -> 0 | K25: =(SUMIF('SG01'!$B:$B,$B25,'SG01'!K:K)*SG01_+SUMIF('SG02'!$B:$B,$B25,'SG02'!K:K)*SG02_+SUMIF('SG03'!$B:$B,$B25,'SG03'!K:K)*SG03_+SUMIF('SG04'!$B:$B,$B25,'SG04'!K:K)*SG04_+SUMIF('SG05'!$B:$B,$B25,'SG05'!K:K)*SG05_+SUMIF('SG06'!$B:$B,$B25,'SG06'!K:K)*SG06_+SUMIF('SG07'!$B:$B,$B25,'SG07'!K:K)*SG07_+SUMIF('SG08'!$B:$B,$B25,'SG08'!K:K)*SG08_+SUMIF('SG09'!$B:$B,$B25,'SG09'!K:K)*SG09_+SUMIF('SG10'!$B:$B,$B25,'SG10'!K:K)*SG10_+SUMIF('SG11'!$B:$B,$B25,'SG11'!K:K)*SG11_+SUMIF('SG12'!$B:$B,$B25,'SG12'!K:K)*SG12_+SUMIF('SG13'!$B:$B,$B25,'SG13'!K:K)*SG13_+SUMIF('SG14'!$B:$B,$B25,'SG14'!K:K)*SG14_+SUMIF('SG15'!$B:$B,$B25,'SG15'!K:K)*SG15_) -> 0 | L25: =(SUMIF('SG01'!$B:$B,$B25,'SG01'!L:L)*SG01_+SUMIF('SG02'!$B:$B,$B25,'SG02'!L:L)*SG02_+SUMIF('SG03'!$B:$B,$B25,'SG03'!L:L)*SG03_+SUMIF('SG04'!$B:$B,$B25,'SG04'!L:L)*SG04_+SUMIF('SG05'!$B:$B,$B25,'SG05'!L:L)*SG05_+SUMIF('SG06'!$B:$B,$B25,'SG06'!L:L)*SG06_+SUMIF('SG07'!$B:$B,$B25,'SG07'!L:L)*SG07_+SUMIF('SG08'!$B:$B,$B25,'SG08'!L:L)*SG08_+SUMIF('SG09'!$B:$B,$B25,'SG09'!L:L)*SG09_+SUMIF('SG10'!$B:$B,$B25,'SG10'!L:L)*SG10_+SUMIF('SG11'!$B:$B,$B25,'SG11'!L:L)*SG11_+SUMIF('SG12'!$B:$B,$B25,'SG12'!L:L)*SG12_+SUMIF('SG13'!$B:$B,$B25,'SG13'!L:L)*SG13_+SUMIF('SG14'!$B:$B,$B25,'SG14'!L:L)*SG14_+SUMIF('SG15'!$B:$B,$B25,'SG15'!L:L)*SG15_) -> 0 | M25: =L25-K25 -> 0 | N25: =K25/L25 -> #DIV/0! | O25: =L25/L$10 -> 0 | P25: =M25/M$10 -> 0 | Q25: =I25/I$10 -> 0 | R25: =I25/$K$5*100 -> 0 | S25: =R25*T$5 -> 0 | T25: =IFERROR(S25*G25,0) -> 0 | V25: =IF(B25<>"",IFERROR(IF($I25>=$X$10,"High","Low"),""),"") -> Low | W25: =IF(B25<>"",IFERROR(IF($L25>=$X$12,"High","Low"),""),"") -> Low | X25: =IF(B25<>"",IFERROR(IF(AND(V25="high",W25="high"),"Star",IF(AND(V25="low",W25="high"),"Puzzle",(IF(AND(V25="high",W25="low"),"Horse","Dog")))),""),"") -> Dog
A26: =+A25+1 -> 9 | B26: GSKVI012 | C26: =VLOOKUP(B26,'SG02'!$B:$E,2,0) -> Khoai Lang Chiên Rong Biển | E26: =VLOOKUP(B26,'SG01'!$B:$E,4,0) -> Phần | F26: =K26/I26 -> 17475.019 | G26: =L26/I26 -> 70833.333 | H26: =G26-F26 -> 53358.314 | I26: =(SUMIF('SG01'!$B:$B,$B26,'SG01'!I:I)*SG01_+SUMIF('SG02'!$B:$B,$B26,'SG02'!I:I)*SG02_+SUMIF('SG03'!$B:$B,$B26,'SG03'!I:I)*SG03_+SUMIF('SG04'!$B:$B,$B26,'SG04'!I:I)*SG04_+SUMIF('SG05'!$B:$B,$B26,'SG05'!I:I)*SG05_+SUMIF('SG06'!$B:$B,$B26,'SG06'!I:I)*SG06_+SUMIF('SG07'!$B:$B,$B26,'SG07'!I:I)*SG07_+SUMIF('SG08'!$B:$B,$B26,'SG08'!I:I)*SG08_+SUMIF('SG09'!$B:$B,$B26,'SG09'!I:I)*SG09_+SUMIF('SG10'!$B:$B,$B26,'SG10'!I:I)*SG10_+SUMIF('SG11'!$B:$B,$B26,'SG11'!I:I)*SG11_+SUMIF('SG12'!$B:$B,$B26,'SG12'!I:I)*SG12_+SUMIF('SG13'!$B:$B,$B26,'SG13'!I:I)*SG13_+SUMIF('SG14'!$B:$B,$B26,'SG14'!I:I)*SG14_+SUMIF('SG15'!$B:$B,$B26,'SG15'!I:I)*SG15_) -> 36 | K26: =(SUMIF('SG01'!$B:$B,$B26,'SG01'!K:K)*SG01_+SUMIF('SG02'!$B:$B,$B26,'SG02'!K:K)*SG02_+SUMIF('SG03'!$B:$B,$B26,'SG03'!K:K)*SG03_+SUMIF('SG04'!$B:$B,$B26,'SG04'!K:K)*SG04_+SUMIF('SG05'!$B:$B,$B26,'SG05'!K:K)*SG05_+SUMIF('SG06'!$B:$B,$B26,'SG06'!K:K)*SG06_+SUMIF('SG07'!$B:$B,$B26,'SG07'!K:K)*SG07_+SUMIF('SG08'!$B:$B,$B26,'SG08'!K:K)*SG08_+SUMIF('SG09'!$B:$B,$B26,'SG09'!K:K)*SG09_+SUMIF('SG10'!$B:$B,$B26,'SG10'!K:K)*SG10_+SUMIF('SG11'!$B:$B,$B26,'SG11'!K:K)*SG11_+SUMIF('SG12'!$B:$B,$B26,'SG12'!K:K)*SG12_+SUMIF('SG13'!$B:$B,$B26,'SG13'!K:K)*SG13_+SUMIF('SG14'!$B:$B,$B26,'SG14'!K:K)*SG14_+SUMIF('SG15'!$B:$B,$B26,'SG15'!K:K)*SG15_) -> 629100.69 | L26: =(SUMIF('SG01'!$B:$B,$B26,'SG01'!L:L)*SG01_+SUMIF('SG02'!$B:$B,$B26,'SG02'!L:L)*SG02_+SUMIF('SG03'!$B:$B,$B26,'SG03'!L:L)*SG03_+SUMIF('SG04'!$B:$B,$B26,'SG04'!L:L)*SG04_+SUMIF('SG05'!$B:$B,$B26,'SG05'!L:L)*SG05_+SUMIF('SG06'!$B:$B,$B26,'SG06'!L:L)*SG06_+SUMIF('SG07'!$B:$B,$B26,'SG07'!L:L)*SG07_+SUMIF('SG08'!$B:$B,$B26,'SG08'!L:L)*SG08_+SUMIF('SG09'!$B:$B,$B26,'SG09'!L:L)*SG09_+SUMIF('SG10'!$B:$B,$B26,'SG10'!L:L)*SG10_+SUMIF('SG11'!$B:$B,$B26,'SG11'!L:L)*SG11_+SUMIF('SG12'!$B:$B,$B26,'SG12'!L:L)*SG12_+SUMIF('SG13'!$B:$B,$B26,'SG13'!L:L)*SG13_+SUMIF('SG14'!$B:$B,$B26,'SG14'!L:L)*SG14_+SUMIF('SG15'!$B:$B,$B26,'SG15'!L:L)*SG15_) -> 2550000 | M26: =L26-K26 -> 1920899.3 | N26: =K26/L26 -> 0.24670615 | O26: =L26/L$10 -> 0.0016445639 | P26: =M26/M$10 -> 0.0018670423 | Q26: =I26/I$10 -> 0.0022427112 | R26: =I26/$K$5*100 -> 0.97481722 | S26: =R26*T$5 -> 2.8639618 | T26: =IFERROR(S26*G26,0) -> 202863.96 | V26: =IF(B26<>"",IFERROR(IF($I26>=$X$10,"High","Low"),""),"") -> Low | W26: =IF(B26<>"",IFERROR(IF($L26>=$X$12,"High","Low"),""),"") -> Low | X26: =IF(B26<>"",IFERROR(IF(AND(V26="high",W26="high"),"Star",IF(AND(V26="low",W26="high"),"Puzzle",(IF(AND(V26="high",W26="low"),"Horse","Dog")))),""),"") -> Dog
A27: =+A26+1 -> 10 | B27: GSKVI013 | C27: =VLOOKUP(B27,'SG02'!$B:$E,2,0) -> Sụn Gà Chiên | E27: =VLOOKUP(B27,'SG01'!$B:$E,4,0) -> Phần | F27: =K27/I27 -> 40652.859 | G27: =L27/I27 -> 121875 | H27: =G27-F27 -> 81222.141 | I27: =(SUMIF('SG01'!$B:$B,$B27,'SG01'!I:I)*SG01_+SUMIF('SG02'!$B:$B,$B27,'SG02'!I:I)*SG02_+SUMIF('SG03'!$B:$B,$B27,'SG03'!I:I)*SG03_+SUMIF('SG04'!$B:$B,$B27,'SG04'!I:I)*SG04_+SUMIF('SG05'!$B:$B,$B27,'SG05'!I:I)*SG05_+SUMIF('SG06'!$B:$B,$B27,'SG06'!I:I)*SG06_+SUMIF('SG07'!$B:$B,$B27,'SG07'!I:I)*SG07_+SUMIF('SG08'!$B:$B,$B27,'SG08'!I:I)*SG08_+SUMIF('SG09'!$B:$B,$B27,'SG09'!I:I)*SG09_+SUMIF('SG10'!$B:$B,$B27,'SG10'!I:I)*SG10_+SUMIF('SG11'!$B:$B,$B27,'SG11'!I:I)*SG11_+SUMIF('SG12'!$B:$B,$B27,'SG12'!I:I)*SG12_+SUMIF('SG13'!$B:$B,$B27,'SG13'!I:I)*SG13_+SUMIF('SG14'!$B:$B,$B27,'SG14'!I:I)*SG14_+SUMIF('SG15'!$B:$B,$B27,'SG15'!I:I)*SG15_) -> 64 | K27: =(SUMIF('SG01'!$B:$B,$B27,'SG01'!K:K)*SG01_+SUMIF('SG02'!$B:$B,$B27,'SG02'!K:K)*SG02_+SUMIF('SG03'!$B:$B,$B27,'SG03'!K:K)*SG03_+SUMIF('SG04'!$B:$B,$B27,'SG04'!K:K)*SG04_+SUMIF('SG05'!$B:$B,$B27,'SG05'!K:K)*SG05_+SUMIF('SG06'!$B:$B,$B27,'SG06'!K:K)*SG06_+SUMIF('SG07'!$B:$B,$B27,'SG07'!K:K)*SG07_+SUMIF('SG08'!$B:$B,$B27,'SG08'!K:K)*SG08_+SUMIF('SG09'!$B:$B,$B27,'SG09'!K:K)*SG09_+SUMIF('SG10'!$B:$B,$B27,'SG10'!K:K)*SG10_+SUMIF('SG11'!$B:$B,$B27,'SG11'!K:K)*SG11_+SUMIF('SG12'!$B:$B,$B27,'SG12'!K:K)*SG12_+SUMIF('SG13'!$B:$B,$B27,'SG13'!K:K)*SG13_+SUMIF('SG14'!$B:$B,$B27,'SG14'!K:K)*SG14_+SUMIF('SG15'!$B:$B,$B27,'SG15'!K:K)*SG15_) -> 2601783 | L27: =(SUMIF('SG01'!$B:$B,$B27,'SG01'!L:L)*SG01_+SUMIF('SG02'!$B:$B,$B27,'SG02'!L:L)*SG02_+SUMIF('SG03'!$B:$B,$B27,'SG03'!L:L)*SG03_+SUMIF('SG04'!$B:$B,$B27,'SG04'!L:L)*SG04_+SUMIF('SG05'!$B:$B,$B27,'SG05'!L:L)*SG05_+SUMIF('SG06'!$B:$B,$B27,'SG06'!L:L)*SG06_+SUMIF('SG07'!$B:$B,$B27,'SG07'!L:L)*SG07_+SUMIF('SG08'!$B:$B,$B27,'SG08'!L:L)*SG08_+SUMIF('SG09'!$B:$B,$B27,'SG09'!L:L)*SG09_+SUMIF('SG10'!$B:$B,$B27,'SG10'!L:L)*SG10_+SUMIF('SG11'!$B:$B,$B27,'SG11'!L:L)*SG11_+SUMIF('SG12'!$B:$B,$B27,'SG12'!L:L)*SG12_+SUMIF('SG13'!$B:$B,$B27,'SG13'!L:L)*SG13_+SUMIF('SG14'!$B:$B,$B27,'SG14'!L:L)*SG14_+SUMIF('SG15'!$B:$B,$B27,'SG15'!L:L)*SG15_) -> 7800000 | M27: =L27-K27 -> 5198217 | N27: =K27/L27 -> 0.33356192 | O27: =L27/L$10 -> 0.0050304309 | P27: =M27/M$10 -> 0.0050524726 | Q27: =I27/I$10 -> 0.0039870421 | R27: =I27/$K$5*100 -> 1.7330084 | S27: =R27*T$5 -> 5.0914877 | T27: =IFERROR(S27*G27,0) -> 620525.06 | V27: =IF(B27<>"",IFERROR(IF($I27>=$X$10,"High","Low"),""),"") -> Low | W27: =IF(B27<>"",IFERROR(IF($L27>=$X$12,"High","Low"),""),"") -> High | X27: =IF(B27<>"",IFERROR(IF(AND(V27="high",W27="high"),"Star",IF(AND(V27="low",W27="high"),"Puzzle",(IF(AND(V27="high",W27="low"),"Horse","Dog")))),""),"") -> Puzzle
